Workbook

Sheet Beam
A1: Element ID | B1: Start Level Offset | C1: Rebar Cover - Top Face | D1: Cut Length | E1: z Offset Value | F1: Work Plane | G1: Join Status | H1: Type | I1: Elevation at Top | J1: z Justification | K1: Length | L1: Phase Created | M1: Elevation at Bottom | N1: Export to IFC | O1: GRADE OF CONCRETE | P1: ID_UNMT | Q1: BEAM WIDTH | R1: Reference Level | S1: Qty: Area (m2) | T1: Category | U1: Cross-Section Rotation | V1: Volume | W1: y Justification | X1: Qty: Volume (m3) | Y1: Has Association | Z1: ROOM NO. | AA1: yz Justification | AB1: Reference Level Elevation | AC1: Rebar Cover - Other Faces | AD1: Type Id | AE1: Family | AF1: Rebar Cover - Bottom Face | AG1: Orientation | AH1: IfcGUID | AI1: End Level Offset | AJ1: Structural Material | AK1: Qty: Length (m) | AL1: Family and Type | AM1: BEAM DEPTH | AN1: y Offset Value | AO1: Structural Usage
A2: 3079902 | B2: 0 | C2: 3178025 | D2: 2900 | E2: 0 | F2: Level : 03 PLINTH LEVEL | G2: One or two joins disabled | H2: 3079709 | I2: 450 | J2: Top | K2: 2900 | L2: 110001 | M2: -100 | N2: By Type | O2: M30 | P2: B10 | Q2: 250 | R2: 2248242 | S2: 2.4575 | T2: -2001320 | U2: 0.00° | V2: 0.40 m³ | W2: Left | X2: 0.3987 | Y2: No | AA2: Uniform | AB2: 450 | AD2: 3079709 | AE2: 3079709 | AF2: 3178025 | AG2: Normal | AH2: 0sZlodXlT3tverCRqGTnXq | AI2: 0 | AJ2: 293562 | AK2: 2.9 | AL2: 3079709 | AM2: 550 | AN2: 0 | AO2: Other
A3: 3080849 | B3: 0 | C3: 3178025 | D3: 2375 | E3: 0 | F3: Level : 03 PLINTH LEVEL | G3: One or two joins disabled | H3: 3079709 | I3: 450 | J3: Top | K3: 2375 | L3: 110001 | M3: -100 | N3: By Type | O3: M30 | P3: B16 | Q3: 250 | R3: 2248242 | S3: 2.0375 | T3: -2001320 | U3: 0.00° | V3: 0.33 m³ | W3: Left | X3: 0.3266 | Y3: No | AA3: Uniform | AB3: 450 | AD3: 3079709 | AE3: 3079709 | AF3: 3178025 | AG3: Normal | AH3: 1_FLm7iHf9TvKSeqPzC2K8 | AI3: 0 | AJ3: 293562 | AK3: 2.375 | AL3: 3079709 | AM3: 550 | AN3: 0 | AO3: Other
A4: 3081145 | B4: 0 | C4: 3178025 | D4: 4350 | E4: 0 | F4: Level : 03 PLINTH LEVEL | G4: One or two joins disabled | H4: 3079709 | I4: 450 | J4: Top | K4: 4350 | L4: 110001 | M4: -100 | N4: By Type | O4: M30 | P4: B2 | Q4: 250 | R4: 2248242 | S4: 3.6175 | T4: -2001320 | U4: 0.00° | V4: 0.60 m³ | W4: Left | X4: 0.5981 | Y4: No | AA4: Uniform | AB4: 450 | AD4: 3079709 | AE4: 3079709 | AF4: 3178025 | AG4: Normal | AH4: 3ueL3jPsfCSw_2nLzW_sbG | AI4: 0 | AJ4: 293562 | AK4: 4.35 | AL4: 3079709 | AM4: 550 | AN4: 0 | AO4: Other
A5: 3081683 | B5: 0 | C5: 3178025 | D5: 600 | E5: 0 | F5: Level : 03 PLINTH LEVEL | G5: One or two joins disabled | H5: 3079709 | I5: 450 | J5: Top | K5: 600 | L5: 110001 | M5: -100 | N5: By Type | O5: M30 | P5: B1 | Q5: 250 | R5: 2248242 | S5: 0.6175 | T5: -2001320 | U5: 0.00° | V5: 0.08 m³ | W5: Left | X5: 0.0825 | Y5: No | AA5: Uniform | AB5: 450 | AC5: 3178025 | AD5: 3079709 | AE5: 3079709 | AF5: 3178025 | AG5: Normal | AH5: 2QOsO1SU19tOnmbHLze0ld | AI5: 0 | AJ5: 293562 | AK5: 0.6 | AL5: 3079709 | AM5: 550 | AN5: 0 | AO5: Other
A6: 3081790 | B6: 0 | C6: 3178025 | D6: 3750 | E6: 0 | F6: Level : 03 PLINTH LEVEL | G6: One or two joins disabled | H6: 3079709 | I6: 450 | J6: Top | K6: 3750 | L6: 110001 | M6: -100 | N6: By Type | O6: M30 | P6: B13 | Q6: 250 | R6: 2248242 | S6: 3.0025 | T6: -2001320 | U6: 0.00° | V6: 0.44 m³ | W6: Left | X6: 0.4414 | Y6: No | AA6: Uniform | AB6: 450 | AD6: 3079709 | AE6: 3079709 | AF6: 3178025 | AG6: Normal | AH6: 0JmCRR8Mv3Ue51A2BTptpQ | AI6: 0 | AJ6: 293562 | AK6: 3.75 | AL6: 3079709 | AM6: 550 | AN6: 0 | AO6: Other
A7: 3081898 | B7: 0 | C7: 3178025 | D7: 3500 | E7: 0 | F7: Level : 03 PLINTH LEVEL | G7: One or two joins disabled | H7: 3089018 | I7: 450 | J7: Top | K7: 3500 | L7: 110001 | M7: -100 | N7: By Type | O7: M30 | P7: B9 | Q7: 200 | R7: 2248242 | S7: 2.735 | T7: -2001320 | U7: 0.00° | V7: 0.39 m³ | W7: Left | X7: 0.385 | Y7: No | AA7: Uniform | AB7: 450 | AC7: 3178025 | AD7: 3089018 | AE7: 3089018 | AF7: 3178025 | AG7: Normal | AH7: 0JmCRR8Mv3Ue51A2BTptnE | AI7: 0 | AJ7: 293562 | AK7: 3.5 | AL7: 3089018 | AM7: 550 | AN7: 0 | AO7: Other
A8: 3082011 | B8: 0 | C8: 3178025 | D8: 4050 | E8: 0 | F8: Level : 03 PLINTH LEVEL | G8: One or two joins disabled | H8: 3181454 | I8: 450 | J8: Top | K8: 4050 | L8: 110001 | M8: -100 | N8: By Type | O8: M30 | P8: B4 | Q8: 200 | R8: 2248242 | S8: 3.14 | T8: -2001320 | U8: 0.00° | V8: 0.44 m³ | W8: Left | X8: 0.4414 | Y8: No | AA8: Uniform | AB8: 450 | AD8: 3181454 | AE8: 3181454 | AF8: 3178025 | AG8: Normal | AH8: 16K_Pi6W9ECvycG_Su1SH8 | AI8: 0 | AJ8: 293562 | AK8: 4.05 | AL8: 3181454 | AM8: 550 | AN8: 0 | AO8: Other
A9: 3082267 | B9: 0 | C9: 3178025 | D9: 1900 | E9: -200 | F9: Level : 03 PLINTH LEVEL | G9: One or two joins disabled | H9: 3181454 | I9: 250 | J9: Top | K9: 1900 | L9: 110001 | M9: -300 | N9: By Type | O9: M30 | P9: B11 | Q9: 200 | R9: 2248242 | S9: 1.535 | T9: -2001320 | U9: 0.00° | V9: 0.21 m³ | W9: Left | X9: 0.209 | Y9: No | AA9: Uniform | AB9: 450 | AC9: 3178025 | AD9: 3181454 | AE9: 3181454 | AF9: 3178025 | AG9: Normal | AH9: 3qutUK42D889pvIpBUtKyU | AI9: 0 | AJ9: 293562 | AK9: 1.9 | AL9: 3181454 | AM9: 550 | AN9: 0 | AO9: Other
A10: 3082514 | B10: 0 | C10: 3178025 | D10: 1400 | E10: 0 | F10: Level : 03 PLINTH LEVEL | G10: One or two joins disabled | H10: 3079709 | I10: 450 | J10: Top | K10: 1400 | L10: 110001 | M10: -100 | N10: By Type | O10: M30 | P10: B5 | Q10: 250 | R10: 2248242 | S10: 1.2575 | T10: -2001320 | U10: 0.00° | V10: 0.19 m³ | W10: Left | X10: 0.1925 | Y10: No | AA10: Uniform | AB10: 450 | AD10: 3079709 | AE10: 3079709 | AF10: 3178025 | AG10: Normal | AH10: 1w7DuRZyT28QZO5z9zRhh8 | AI10: 0 | AJ10: 293562 | AK10: 1.4 | AL10: 3079709 | AM10: 550 | AN10: 0 | AO10: Other
A11: 3082627 | B11: 0 | C11: 3178025 | D11: 1850 | E11: 0 | F11: Level : 03 PLINTH LEVEL | G11: One or two joins disabled | H11: 3079709 | I11: 450 | J11: Top | K11: 1850 | L11: 110001 | M11: -100 | N11: By Type | O11: M30 | P11: B3 | Q11: 250 | R11: 2248242 | S11: 1.6175 | T11: -2001320 | U11: 0.00° | V11: 0.25 m³ | W11: Left | X11: 0.2544 | Y11: No | AA11: Uniform | AB11: 450 | AD11: 3079709 | AE11: 3079709 | AF11: 3178025 | AG11: Normal | AH11: 1WbrjRl9L8V9UleaBo896L | AI11: 0 | AJ11: 293562 | AK11: 1.85 | AL11: 3079709 | AM11: 550 | AN11: 0 | AO11: Other
A12: 3082731 | B12: 0 | C12: 3178025 | D12: 5100 | E12: 0 | F12: Level : 03 PLINTH LEVEL | G12: One or two joins disabled | H12: 3079709 | I12: 450 | J12: Top | K12: 5100 | L12: 110001 | M12: -100 | N12: By Type | O12: M30 | P12: B15 | Q12: 250 | R12: 2248242 | S12: 4.2175 | T12: -2001320 | U12: 0.00° | V12: 0.70 m³ | W12: Left | X12: 0.7013 | Y12: No | AA12: Uniform | AB12: 450 | AD12: 3079709 | AE12: 3079709 | AF12: 3178025 | AG12: Normal | AH12: 1WbrjRl9L8V9UleaBo897z | AI12: 0 | AJ12: 293562 | AK12: 5.1 | AL12: 3079709 | AM12: 550 | AN12: 0 | AO12: Other
A13: 3082921 | B13: 0 | C13: 3178025 | D13: 8600 | E13: 0 | F13: Level : 03 PLINTH LEVEL | G13: One or two joins disabled | H13: 3083275 | I13: 450 | J13: Top | K13: 8600 | L13: 110001 | M13: -100 | N13: By Type | O13: M30 | P13: B6 | Q13: 300 | R13: 2248242 | S13: 7.475 | T13: -2001320 | U13: 0.00° | V13: 1.42 m³ | W13: Right | X13: 1.419 | Y13: No | AA13: Uniform | AB13: 450 | AC13: 3178025 | AD13: 3083275 | AE13: 3083275 | AF13: 3178025 | AG13: Normal | AH13: 0Zmr2B1_X81OwsbsfMe5Lp | AI13: 0 | AJ13: 293562 | AK13: 8.6 | AL13: 3083275 | AM13: 550 | AN13: 0 | AO13: Other
A14: 3083476 | B14: 0 | C14: 3178025 | D14: 5160 | E14: 0 | F14: Level : 03 PLINTH LEVEL | G14: One or two joins disabled | H14: 3079709 | I14: 450 | J14: Top | K14: 5160 | L14: 110001 | M14: -100 | N14: By Type | O14: M30 | P14: B7 | Q14: 250 | R14: 2248242 | S14: 4.2655 | T14: -2001320 | U14: 0.00° | V14: 0.71 m³ | W14: Right | X14: 0.7095 | Y14: No | AA14: Uniform | AB14: 450 | AC14: 3178025 | AD14: 3079709 | AE14: 3079709 | AF14: 3178025 | AG14: Normal | AH14: 2utMYCOmrDffed6MpfxG0E | AI14: 0 | AJ14: 293562 | AK14: 5.16 | AL14: 3079709 | AM14: 550 | AN14: 0 | AO14: Other
A15: 3083539 | B15: 0 | C15: 3178025 | D15: 3850 | E15: 0 | F15: Level : 03 PLINTH LEVEL | G15: One or two joins disabled | H15: 3079709 | I15: 450 | J15: Top | K15: 3850 | L15: 110001 | M15: -100 | N15: By Type | O15: M30 | P15: B8 | Q15: 250 | R15: 2248242 | S15: 3.2175 | T15: -2001320 | U15: 0.00° | V15: 0.53 m³ | W15: Left | X15: 0.5294 | Y15: No | AA15: Uniform | AB15: 450 | AC15: 3178025 | AD15: 3079709 | AE15: 3079709 | AF15: 3178025 | AG15: Normal | AH15: 2utMYCOmrDffed6MpfxG79 | AI15: 0 | AJ15: 293562 | AK15: 3.85 | AL15: 3079709 | AM15: 550 | AN15: 0 | AO15: Other
A16: 3083594 | B16: 0 | C16: 3178025 | D16: 3850 | E16: 0 | F16: Level : 03 PLINTH LEVEL | G16: One or two joins disabled | H16: 3079709 | I16: 450 | J16: Top | K16: 3850 | L16: 110001 | M16: -100 | N16: By Type | O16: M30 | P16: B12 | Q16: 250 | R16: 2248242 | S16: 3.2175 | T16: -2001320 | U16: 0.00° | V16: 0.53 m³ | W16: Left | X16: 0.5294 | Y16: No | AA16: Uniform | AB16: 450 | AC16: 3178025 | AD16: 3079709 | AE16: 3079709 | AF16: 3178025 | AG16: Normal | AH16: 2utMYCOmrDffed6MpfxG6G | AI16: 0 | AJ16: 293562 | AK16: 3.85 | AL16: 3079709 | AM16: 550 | AN16: 0 | AO16: Other
A17: 3085142 | B17: 0 | C17: 3178025 | D17: 2300 | E17: 0 | F17: Level : 03 PLINTH LEVEL | G17: One or two joins disabled | H17: 3079709 | I17: 450 | J17: Top | K17: 2300 | L17: 110001 | M17: -100 | N17: By Type | O17: M30 | P17: B17 | Q17: 250 | R17: 2248242 | S17: 1.9775 | T17: -2001320 | U17: 0.00° | V17: 0.32 m³ | W17: Left | X17: 0.3163 | Y17: No | AA17: Uniform | AB17: 450 | AD17: 3079709 | AE17: 3079709 | AF17: 3178025 | AG17: Normal | AH17: 0BBj8nW1D6ae_3yS5pWgAv | AI17: 0 | AJ17: 293562 | AK17: 2.3 | AL17: 3079709 | AM17: 550 | AN17: 0 | AO17: Other
A18: 3108891 | B18: 0 | C18: 3178025 | D18: 600 | E18: 0 | F18: Level : 04 1ST LEVEL | G18: One or two joins disabled | H18: 3089018 | I18: 6000 | J18: Top | K18: 600 | L18: 110001 | M18: 5450 | N18: By Type | O18: M30 | P18: B44 | Q18: 200 | R18: 2248367 | S18: 0.56 | T18: -2001320 | U18: 0.00° | V18: 0.07 m³ | W18: Left | X18: 0.066 | Y18: No | AA18: Uniform | AB18: 6000 | AC18: 3178025 | AD18: 3089018 | AE18: 3089018 | AF18: 3178025 | AG18: Normal | AH18: 1Yaf6MhzfD4f6xf1L8Ohw$ | AI18: 0 | AJ18: 293562 | AK18: 0.6 | AL18: 3089018 | AM18: 550 | AN18: 0 | AO18: Other
A19: 3108893 | B19: 0 | C19: 3178025 | D19: 2450 | E19: 0 | F19: Level : 04 1ST LEVEL | G19: One or two joins disabled | H19: 3089018 | I19: 6000 | J19: Top | K19: 2450 | L19: 110001 | M19: 5450 | N19: By Type | O19: M30 | P19: B1 | Q19: 200 | R19: 2248367 | S19: 1.9475 | T19: -2001320 | U19: 0.00° | V19: 0.27 m³ | W19: Right | X19: 0.2695 | Y19: No | AA19: Uniform | AB19: 6000 | AC19: 3178025 | AD19: 3089018 | AE19: 3089018 | AF19: 3178025 | AG19: Normal | AH19: 1Yaf6MhzfD4f6xf1L8Ohwv | AI19: 0 | AJ19: 293562 | AK19: 2.45 | AL19: 3089018 | AM19: 550 | AN19: 0 | AO19: Other
A20: 3108895 | B20: 0 | C20: 3178025 | D20: 600 | E20: 0 | F20: Level : 04 1ST LEVEL | G20: One or two joins disabled | H20: 3089018 | I20: 6000 | J20: Top | K20: 600 | L20: 110001 | M20: 5450 | N20: By Type | O20: M30 | P20: B37 | Q20: 200 | R20: 2248367 | S20: 0.56 | T20: -2001320 | U20: 0.00° | V20: 0.07 m³ | W20: Right | X20: 0.066 | Y20: No | AA20: Uniform | AB20: 6000 | AC20: 3178025 | AD20: 3089018 | AE20: 3089018 | AF20: 3178025 | AG20: Normal | AH20: 1Yaf6MhzfD4f6xf1L8Ohwx | AI20: 0 | AJ20: 293562 | AK20: 0.6 | AL20: 3089018 | AM20: 550 | AN20: 0 | AO20: Other
A21: 3108897 | B21: 0 | C21: 3178025 | D21: 150 | E21: 0 | F21: Level : 04 1ST LEVEL | G21: One or two joins disabled | H21: 3089020 | I21: 6000 | J21: Top | K21: 150 | L21: 110001 | M21: 5450 | N21: By Type | O21: M30 | P21: B2A | Q21: 300 | R21: 2248367 | S21: 0.2925 | T21: -2001320 | U21: 0.00° | V21: 0.02 m³ | W21: Right | X21: 0.0247 | Y21: No | AA21: Uniform | AB21: 6000 | AC21: 3178025 | AD21: 3089020 | AE21: 3089020 | AF21: 3178025 | AG21: Normal | AH21: 1Yaf6MhzfD4f6xf1L8Ohw5 | AI21: 0 | AJ21: 293562 | AK21: 0.15 | AL21: 3089020 | AM21: 550 | AN21: 0 | AO21: Other
A22: 3108899 | B22: 0 | C22: 3178025 | D22: 150 | E22: 0 | F22: Level : 04 1ST LEVEL | G22: One or two joins disabled | H22: 3089020 | I22: 6000 | J22: Top | K22: 150 | L22: 110001 | M22: 5450 | N22: By Type | O22: M30 | P22: B2A | Q22: 300 | R22: 2248367 | S22: 0.2925 | T22: -2001320 | U22: 0.00° | V22: 0.02 m³ | W22: Left | X22: 0.0248 | Y22: No | AA22: Uniform | AB22: 6000 | AC22: 3178025 | AD22: 3089020 | AE22: 3089020 | AF22: 3178025 | AG22: Normal | AH22: 1Yaf6MhzfD4f6xf1L8Ohw7 | AI22: 0 | AJ22: 293562 | AK22: 0.15 | AL22: 3089020 | AM22: 550 | AN22: 0 | AO22: Other
A23: 3108901 | B23: 0 | C23: 3178025 | D23: 3700 | E23: 0 | F23: Level : 04 1ST LEVEL | G23: One or two joins disabled | H23: 3089018 | I23: 6000 | J23: Top | K23: 3700 | L23: 110001 | M23: 5450 | N23: By Type | O23: M30 | P23: B32 | Q23: 200 | R23: 2248367 | S23: 2.885 | T23: -2001320 | U23: 0.00° | V23: 0.41 m³ | W23: Right | X23: 0.407 | Y23: No | AA23: Uniform | AB23: 6000 | AC23: 3178025 | AD23: 3089018 | AE23: 3089018 | AF23: 3178025 | AG23: Normal | AH23: 1Yaf6MhzfD4f6xf1L8Ohw1 | AI23: 0 | AJ23: 293562 | AK23: 3.7 | AL23: 3089018 | AM23: 550 | AN23: 0 | AO23: Other
A24: 3108903 | B24: 0 | C24: 3178025 | D24: 900 | E24: 0 | F24: Level : 04 1ST LEVEL | G24: One or two joins disabled | H24: 3089018 | I24: 6000 | J24: Top | K24: 900 | L24: 110001 | M24: 5450 | N24: By Type | O24: M30 | P24: B6 | Q24: 200 | R24: 2248367 | S24: 0.785 | T24: -2001320 | U24: 0.00° | V24: 0.10 m³ | W24: Right | X24: 0.099 | Y24: No | AA24: Uniform | AB24: 6000 | AC24: 3178025 | AD24: 3089018 | AE24: 3089018 | AF24: 3178025 | AG24: Normal | AH24: 1Yaf6MhzfD4f6xf1L8Ohw3 | AI24: 0 | AJ24: 293562 | AK24: 0.9 | AL24: 3089018 | AM24: 550 | AN24: 0 | AO24: Other
A25: 3108905 | B25: 0 | C25: 3178025 | D25: 550 | E25: 0 | F25: Level : 04 1ST LEVEL | G25: One or two joins disabled | H25: 3089020 | I25: 6000 | J25: Top | K25: 550 | L25: 110001 | M25: 5450 | N25: By Type | O25: M30 | P25: B3 | Q25: 300 | R25: 2248367 | S25: 0.6325 | T25: -2001320 | U25: 0.00° | V25: 0.09 m³ | W25: Right | X25: 0.0908 | Y25: No | AA25: Uniform | AB25: 6000 | AC25: 3178025 | AD25: 3089020 | AE25: 3089020 | AF25: 3178025 | AG25: Normal | AH25: 1Yaf6MhzfD4f6xf1L8OhwD | AI25: 0 | AJ25: 293562 | AK25: 0.55 | AL25: 3089020 | AM25: 550 | AN25: 0 | AO25: Other
A26: 3108907 | B26: 0 | C26: 3178025 | D26: 8500 | E26: 0 | F26: Level : 04 1ST LEVEL | G26: One or two joins disabled | H26: 3089020 | I26: 6000 | J26: Top | K26: 8500 | L26: 110001 | M26: 5450 | N26: By Type | O26: M30 | P26: B2 | Q26: 300 | R26: 2248367 | S26: 7.39 | T26: -2001320 | U26: 0.00° | V26: 1.40 m³ | W26: Left | X26: 1.4025 | Y26: No | AA26: Uniform | AB26: 6000 | AC26: 3178025 | AD26: 3089020 | AE26: 3089020 | AF26: 3178025 | AG26: Normal | AH26: 1Yaf6MhzfD4f6xf1L8OhwF | AI26: 0 | AJ26: 293562 | AK26: 8.5 | AL26: 3089020 | AM26: 550 | AN26: 0 | AO26: Other
A27: 3108909 | B27: 0 | C27: 3178025 | D27: 4450 | E27: 0 | F27: Level : 04 1ST LEVEL | G27: One or two joins disabled | H27: 3089018 | I27: 6000 | J27: Top | K27: 4450 | L27: 110001 | M27: 5450 | N27: By Type | O27: M30 | P27: B52 | Q27: 200 | R27: 2248367 | S27: 3.4475 | T27: -2001320 | U27: 0.00° | V27: 0.49 m³ | W27: Left | X27: 0.4895 | Y27: No | AA27: Uniform | AB27: 6000 | AC27: 3178025 | AD27: 3089018 | AE27: 3089018 | AF27: 3178025 | AG27: Normal | AH27: 1Yaf6MhzfD4f6xf1L8Ohw9 | AI27: 0 | AJ27: 293562 | AK27: 4.45 | AL27: 3089018 | AM27: 550 | AN27: 0 | AO27: Other
A28: 3108911 | B28: 0 | C28: 3178025 | D28: 900 | E28: 0 | F28: Level : 04 1ST LEVEL | G28: One or two joins disabled | H28: 3089018 | I28: 6000 | J28: Top | K28: 900 | L28: 110001 | M28: 5450 | N28: By Type | O28: M30 | P28: B9 | Q28: 200 | R28: 2248367 | S28: 0.785 | T28: -2001320 | U28: 0.00° | V28: 0.10 m³ | W28: Left | X28: 0.099 | Y28: No | AA28: Uniform | AB28: 6000 | AC28: 3178025 | AD28: 3089018 | AE28: 3089018 | AF28: 3178025 | AG28: Normal | AH28: 1Yaf6MhzfD4f6xf1L8OhwB | AI28: 0 | AJ28: 293562 | AK28: 0.9 | AL28: 3089018 | AM28: 550 | AN28: 0 | AO28: Other
A29: 3108913 | B29: 0 | C29: 3178025 | D29: 3000 | E29: 0 | F29: Level : 04 1ST LEVEL | G29: One or two joins disabled | H29: 3089018 | I29: 6000 | J29: Top | K29: 3000 | L29: 110001 | M29: 5450 | N29: By Type | O29: M30 | P29: B36 | Q29: 200 | R29: 2248367 | S29: 2.36 | T29: -2001320 | U29: 0.00° | V29: 0.33 m³ | W29: Right | X29: 0.33 | Y29: No | AA29: Uniform | AB29: 6000 | AC29: 3178025 | AD29: 3089018 | AE29: 3089018 | AF29: 3178025 | AG29: Normal | AH29: 1Yaf6MhzfD4f6xf1L8OhwL | AI29: 0 | AJ29: 293562 | AK29: 3 | AL29: 3089018 | AM29: 550 | AN29: 0 | AO29: Other
... A33: 3108921 | B33: 0 | C33: 3178025 | D33: 1150 | E33: -200 | F33: Level : 04 1ST LEVEL | G33: One or two joins disabled | H33: 3089028 | I33: 5800 | J33: Top | K33: 1150 | L33: 110001 | M33: 5450 | N33: By Type | O33: M30 | P33: B4 | Q33: 200 | R33: 2248367 | S33: 0.7025 | T33: -2001320 | U33: 0.00° | V33: 0.08 m³ | W33: Right | X33: 0.0805 | Y33: No | AA33: Uniform | AB33: 6000 | AC33: 3178025 | AD33: 3089028 | AE33: 3089028 | AF33: 3178025 | AG33: Normal | AH33: 1Yaf6MhzfD4f6xf1L8OhwT | AI33: 0 | AJ33: 293562 | AK33: 1.15 | AL33: 3089028 | AM33: 350 | AN33: 0 | AO33: Other
A34: 3108923 | B34: 0 | C34: 3178025 | D34: 4450 | E34: 0 | F34: Level : 04 1ST LEVEL | G34: One or two joins disabled | H34: 3089018 | I34: 6000 | J34: Top | K34: 4450 | L34: 110001 | M34: 5450 | N34: By Type | O34: M30 | P34: B42 | Q34: 200 | R34: 2248367 | S34: 3.4475 | T34: -2001320 | U34: 0.00° | V34: 0.49 m³ | W34: Right | X34: 0.4895 | Y34: No | AA34: Uniform | AB34: 6000 | AD34: 3089018 | AE34: 3089018 | AF34: 3178025 | AG34: Normal | AH34: 1Yaf6MhzfD4f6xf1L8OhwV | AI34: 0 | AJ34: 293562 | AK34: 4.45 | AL34: 3089018 | AM34: 550 | AN34: 0 | AO34: Other
A35: 3108925 | B35: 0 | C35: 3178025 | D35: 8000 | E35: 0 | F35: Level : 04 1ST LEVEL | G35: One or two joins disabled | H35: 3089020 | I35: 6000 | J35: Top | K35: 8000 | L35: 110001 | M35: 5450 | N35: By Type | O35: M30 | P35: B11 | Q35: 300 | R35: 2248367 | S35: 6.965 | T35: -2001320 | U35: 0.00° | V35: 1.32 m³ | W35: Left | X35: 1.32 | Y35: No | AA35: Uniform | AB35: 6000 | AC35: 3178025 | AD35: 3089020 | AE35: 3089020 | AF35: 3178025 | AG35: Normal | AH35: 1Yaf6MhzfD4f6xf1L8OhwP | AI35: 0 | AJ35: 293562 | AK35: 8 | AL35: 3089020 | AM35: 550 | AN35: 0 | AO35: Other
A36: 3108927 | B36: 0 | C36: 3178025 | D36: 1250 | E36: 0 | F36: Level : 04 1ST LEVEL | G36: One or two joins disabled | H36: 3089018 | I36: 6000 | J36: Top | K36: 1250 | L36: 110001 | M36: 5450 | N36: By Type | O36: M30 | P36: B28 | Q36: 200 | R36: 2248367 | S36: 1.0475 | T36: -2001320 | U36: 0.00° | V36: 0.14 m³ | W36: Right | X36: 0.1375 | Y36: No | AA36: Uniform | AB36: 6000 | AC36: 3178025 | AD36: 3089018 | AE36: 3089018 | AF36: 3178025 | AG36: Normal | AH36: 1Yaf6MhzfD4f6xf1L8OhwR | AI36: 0 | AJ36: 293562 | AK36: 1.25 | AL36: 3089018 | AM36: 550 | AN36: 0 | AO36: Other
A37: 3108929 | B37: 0 | C37: 3178025 | D37: 900 | E37: 0 | F37: Level : 04 1ST LEVEL | G37: One or two joins disabled | H37: 3089018 | I37: 6000 | J37: Top | K37: 900 | L37: 110001 | M37: 5450 | N37: By Type | O37: M30 | P37: B10 | Q37: 200 | R37: 2248367 | S37: 0.785 | T37: -2001320 | U37: 0.00° | V37: 0.10 m³ | W37: Left | X37: 0.099 | Y37: No | AA37: Uniform | AB37: 6000 | AC37: 3178025 | AD37: 3089018 | AE37: 3089018 | AF37: 3178025 | AG37: Normal | AH37: 1Yaf6MhzfD4f6xf1L8Ohxb | AI37: 0 | AJ37: 293562 | AK37: 0.9 | AL37: 3089018 | AM37: 550 | AN37: 0 | AO37: Other
A38: 3108931 | B38: 0 | C38: 3178025 | D38: 1110 | E38: 0 | F38: Level : 04 1ST LEVEL | G38: One or two joins disabled | H38: 3089020 | I38: 6000 | J38: Top | K38: 1110 | L38: 110001 | M38: 5450 | N38: By Type | O38: M30 | P38: B12 | Q38: 300 | R38: 2248367 | S38: 1.1085 | T38: -2001320 | U38: 0.00° | V38: 0.18 m³ | W38: Left | X38: 0.1832 | Y38: No | AA38: Uniform | AB38: 6000 | AC38: 3178025 | AD38: 3089020 | AE38: 3089020 | AF38: 3178025 | AG38: Normal | AH38: 1Yaf6MhzfD4f6xf1L8Ohxd | AI38: 0 | AJ38: 293562 | AK38: 1.11 | AL38: 3089020 | AM38: 550 | AN38: 0 | AO38: Other
A39: 3108933 | B39: 0 | C39: 3178025 | D39: 1250 | E39: 0 | F39: Level : 04 1ST LEVEL | G39: One or two joins disabled | H39: 3089018 | I39: 6000 | J39: Top | K39: 1250 | L39: 110001 | M39: 5450 | N39: By Type | O39: M30 | P39: B55 | Q39: 200 | R39: 2248367 | S39: 1.0475 | T39: -2001320 | U39: 0.00° | V39: 0.14 m³ | W39: Left | X39: 0.1375 | Y39: No | AA39: Uniform | AB39: 6000 | AC39: 3178025 | AD39: 3089018 | AE39: 3089018 | AF39: 3178025 | AG39: Normal | AH39: 1Yaf6MhzfD4f6xf1L8OhxX | AI39: 0 | AJ39: 293562 | AK39: 1.25 | AL39: 3089018 | AM39: 550 | AN39: 0 | AO39: Other
A40: 3108935 | B40: 0 | C40: 3178025 | D40: 2900 | E40: 0 | F40: Level : 04 1ST LEVEL | G40: One or two joins disabled | H40: 3089018 | I40: 6000 | J40: Top | K40: 2900 | L40: 110001 | M40: 5450 | N40: By Type | O40: M30 | P40: B31 | Q40: 200 | R40: 2248367 | S40: 2.285 | T40: -2001320 | U40: 0.00° | V40: 0.32 m³ | W40: Right | X40: 0.319 | Y40: No | AA40: Uniform | AB40: 6000 | AC40: 3178025 | AD40: 3089018 | AE40: 3089018 | AF40: 3178025 | AG40: Normal | AH40: 1Yaf6MhzfD4f6xf1L8OhxZ | AI40: 0 | AJ40: 293562 | AK40: 2.9 | AL40: 3089018 | AM40: 550 | AN40: 0 | AO40: Other
A41: 3108937 | B41: 0 | C41: 3178025 | D41: 5150 | E41: 0 | F41: Level : 04 1ST LEVEL | G41: One or two joins disabled | H41: 3089024 | I41: 6000 | J41: Top | K41: 5150 | L41: 110001 | M41: 5450 | N41: By Type | O41: M30 | P41: B54 | Q41: 250 | R41: 2248367 | S41: 4.2575 | T41: -2001320 | U41: 0.00° | V41: 0.71 m³ | W41: Left | X41: 0.7081 | Y41: No | AA41: Uniform | AB41: 6000 | AC41: 3178025 | AD41: 3089024 | AE41: 3089024 | AF41: 3178025 | AG41: Normal | AH41: 1Yaf6MhzfD4f6xf1L8Ohxj | AI41: 0 | AJ41: 293562 | AK41: 5.15 | AL41: 3089024 | AM41: 550 | AN41: 0 | AO41: Other
A42: 3108939 | B42: 0 | C42: 3178025 | D42: 600 | E42: 0 | F42: Level : 04 1ST LEVEL | G42: One or two joins disabled | H42: 3089024 | I42: 6000 | J42: Top | K42: 600 | L42: 110001 | M42: 5450 | N42: By Type | O42: M30 | P42: B13 | Q42: 250 | R42: 2248367 | S42: 0.6175 | T42: -2001320 | U42: 0.00° | V42: 0.08 m³ | W42: Left | X42: 0.0825 | Y42: No | AA42: Uniform | AB42: 6000 | AC42: 3178025 | AD42: 3089024 | AE42: 3089024 | AF42: 3178025 | AG42: Normal | AH42: 1Yaf6MhzfD4f6xf1L8Ohxl | AI42: 0 | AJ42: 293562 | AK42: 0.6 | AL42: 3089024 | AM42: 550 | AN42: 0 | AO42: Other
A43: 3108941 | B43: 0 | C43: 3178025 | D43: 6010 | E43: 0 | F43: Level : 04 1ST LEVEL | G43: One or two joins disabled | H43: 3089024 | I43: 6000 | J43: Top | K43: 6010 | L43: 110001 | M43: 5450 | N43: By Type | O43: M30 | P43: B14 | Q43: 250 | R43: 2248367 | S43: 4.9455 | T43: -2001320 | U43: 0.00° | V43: 0.83 m³ | W43: Left | X43: 0.8264 | Y43: No | AA43: Uniform | AB43: 6000 | AC43: 3178025 | AD43: 3089024 | AE43: 3089024 | AF43: 3178025 | AG43: Normal | AH43: 1Yaf6MhzfD4f6xf1L8Ohxf | AI43: 0 | AJ43: 293562 | AK43: 6.01 | AL43: 3089024 | AM43: 550 | AN43: 0 | AO43: Other
...

Sheet Column
A1: Element ID | B1: Level | C1: Rebar Cover - Top Face | D1: Moves With Grids | E1: Top Level | F1: Type | G1: Length | H1: Phase Created | I1: Export to IFC | J1: GRADE OF CONCRETE | K1: Base Offset | L1: ID_UNMT | M1: Top Offset | N1: Qty: Area (m2) | O1: Category | P1: Volume | Q1: Base Level | R1: Room Bounding | S1: Qty: Volume (m3) | T1: Has Association | U1: Column Style | V1: Rebar Cover - Other Faces | W1: Type Id | X1: Family | Y1: Rebar Cover - Bottom Face | Z1: IfcGUID | AA1: Structural Material | AB1: Qty: Length (m) | AC1: Family and Type
A2: 3072170 | B2: 2248493 | C2: 124652 | D2: Yes | E2: 2248242 | F2: 2270699 | G2: 2800 | H2: 110001 | I2: By Type | J2: M40 | K2: 0 | L2: P31 | M2: 0 | N2: 3.63 | O2: -2001330 | P2: 0.76 m³ | Q2: 2248493 | R2: Yes | S2: 0.756 | T2: No | U2: Vertical | V2: 124652 | W2: 2270699 | X2: 2270699 | Y2: 124652 | Z2: 1cOR_VX$r0AOI0dQYfFQzi | AA2: 230012 | AB2: 2.8 | AC2: 2270699
A3: 3072220 | B3: 2248493 | C3: 124652 | D3: Yes | E3: 2248242 | F3: 3113818 | G3: 2800 | H3: 110001 | I3: By Type | J3: M40 | K3: 0 | M3: 0 | N3: 3.32 | O3: -2001330 | P3: 0.67 m³ | Q3: 2248493 | R3: Yes | S3: 0.672 | T3: No | U3: Vertical | V3: 124652 | W3: 3113818 | X3: 3113818 | Y3: 124652 | Z3: 3g$5deWJz9Pw1ItRzeIhWG | AA3: 230012 | AB3: 2.8 | AC3: 3113818
A4: 3072869 | B4: 2248493 | C4: 124652 | D4: Yes | E4: 2248242 | F4: 3072865 | G4: 2800 | H4: 110001 | I4: By Type | J4: M40 | K4: 0 | M4: 0 | N4: 4.04 | O4: -2001330 | P4: 1.12 m³ | Q4: 2248493 | R4: Yes | S4: 1.12 | T4: No | U4: Vertical | V4: 124652 | W4: 3072865 | X4: 3072865 | Z4: 2ohiwoKjf239MUfP$H_zLU | AA4: 230012 | AB4: 2.8 | AC4: 3072865
A5: 3072935 | B5: 2248493 | C5: 124652 | D5: Yes | E5: 2248242 | F5: 3080622 | G5: 2800 | H5: 110001 | I5: By Type | J5: M40 | K5: 0 | M5: 0 | N5: 4.0225 | O5: -2001330 | P5: 1.07 m³ | Q5: 2248493 | R5: Yes | S5: 1.071 | T5: No | U5: Vertical | V5: 124652 | W5: 3080622 | X5: 3080622 | Y5: 124652 | Z5: 279mmlFkP8VQg8p_cJohR9 | AA5: 230012 | AB5: 2.8 | AC5: 3080622
A6: 3073001 | B6: 2248493 | C6: 124652 | D6: Yes | E6: 2248242 | F6: 3072997 | G6: 2800 | H6: 110001 | I6: By Type | J6: M40 | K6: 0 | M6: 0 | N6: 6.6475 | O6: -2001330 | P6: 1.37 m³ | Q6: 2248493 | R6: Yes | S6: 1.365 | T6: No | U6: Vertical | V6: 124652 | W6: 3072997 | X6: 3072997 | Y6: 124652 | Z6: 3qVNAAsVTApum02lPcqKEt | AA6: 230012 | AB6: 2.8 | AC6: 3072997
A7: 3073025 | B7: 2248493 | C7: 124652 | D7: Yes | E7: 2248242 | F7: 3073021 | G7: 2800 | H7: 110001 | I7: By Type | J7: M40 | K7: 0 | M7: 0 | N7: 1.46 | O7: -2001330 | P7: 0.17 m³ | Q7: 2248493 | R7: Yes | S7: 0.168 | T7: No | U7: Vertical | V7: 124652 | W7: 3073021 | X7: 3073021 | Y7: 124652 | Z7: 3qVNAAsVTApum02lPcqKHV | AA7: 230012 | AB7: 2.8 | AC7: 3073021
A8: 3075646 | B8: 2248493 | C8: 124652 | D8: Yes | E8: 2248242 | F8: 3075811 | G8: 2800 | H8: 110001 | I8: By Type | J8: M40 | K8: 0 | M8: 0 | N8: 6.6475 | O8: -2001330 | P8: 1.37 m³ | Q8: 2248493 | R8: Yes | S8: 1.365 | T8: No | U8: Vertical | V8: 124652 | W8: 3075811 | X8: 3075811 | Y8: 124652 | Z8: 2Gt5m7wB13Yu3J4t117AYf | AA8: 230012 | AB8: 2.8 | AC8: 3075811
A9: 3075703 | B9: 2248493 | C9: 124652 | D9: Yes | E9: 2248242 | F9: 3075838 | G9: 2800 | H9: 110001 | I9: By Type | J9: M40 | K9: 0 | M9: 0 | N9: 2.7588 | O9: -2001330 | P9: 0.47 m³ | Q9: 2248493 | R9: Yes | S9: 0.4725 | T9: No | U9: Vertical | V9: 124652 | W9: 3075838 | X9: 3075838 | Y9: 124652 | Z9: 2Gt5m7wB13Yu3J4t117AZW | AA9: 230012 | AB9: 2.8 | AC9: 3075838
A10: 3076026 | B10: 2248493 | C10: 124652 | D10: Yes | E10: 2248242 | F10: 3076022 | G10: 2800 | H10: 110001 | I10: By Type | J10: M40 | K10: 0 | M10: 0 | N10: 5.885 | O10: -2001330 | P10: 1.19 m³ | Q10: 2248493 | R10: Yes | S10: 1.19 | T10: No | U10: Vertical | V10: 124652 | W10: 3076022 | X10: 3076022 | Y10: 124652 | Z10: 1JkEnnoEj7aw8NfVQaT7HK | AA10: 230012 | AB10: 2.8 | AC10: 3076022
A11: 3076226 | B11: 2248493 | C11: 124652 | D11: Yes | E11: 2248242 | F11: 3076222 | G11: 2800 | H11: 110001 | I11: By Type | J11: M40 | K11: 0 | M11: 0 | N11: 3.04 | O11: -2001330 | P11: 0.67 m³ | Q11: 2248493 | R11: Yes | S11: 0.672 | T11: No | U11: Vertical | V11: 124652 | W11: 3076222 | X11: 3076222 | Y11: 124652 | Z11: 2ovWY3igbER80XEiIP5Z1M | AA11: 230012 | AB11: 2.8 | AC11: 3076222
A12: 3076643 | B12: 2248493 | C12: 124652 | D12: Yes | E12: 2248242 | F12: 3076639 | G12: 2800 | H12: 110001 | I12: By Type | J12: M40 | K12: 0 | M12: 0 | N12: 10.72 | O12: -2001330 | P12: 3.36 m³ | Q12: 2248493 | R12: Yes | S12: 3.36 | T12: No | U12: Vertical | V12: 124652 | W12: 3076639 | X12: 3076639 | Y12: 124652 | Z12: 3AGwxIsxDFSPW7X3sFtVlp | AA12: 230012 | AB12: 2.8 | AC12: 3076639
A13: 3076721 | B13: 2248493 | C13: 124652 | D13: Yes | E13: 2248242 | F13: 3076717 | G13: 2800 | H13: 110001 | I13: By Type | J13: M40 | K13: 0 | M13: 0 | N13: 3.94 | O13: -2001330 | P13: 0.84 m³ | Q13: 2248493 | R13: Yes | S13: 0.84 | T13: No | U13: Vertical | V13: 124652 | W13: 3076717 | X13: 3076717 | Y13: 124652 | Z13: 1E5fPVYML1B9eG4TrHYjpN | AA13: 230012 | AB13: 2.8 | AC13: 3076717
A14: 3076756 | B14: 2248493 | C14: 124652 | D14: Yes | E14: 2248242 | F14: 3076752 | G14: 2800 | H14: 110001 | I14: By Type | J14: M40 | K14: 0 | M14: 0 | N14: 4 | O14: -2001330 | P14: 1.01 m³ | Q14: 2248493 | R14: Yes | S14: 1.008 | T14: No | U14: Vertical | V14: 124652 | W14: 3076752 | X14: 3076752 | Y14: 124652 | Z14: 1E5fPVYML1B9eG4TrHYjmo | AA14: 230012 | AB14: 2.8 | AC14: 3076752
A15: 3076782 | B15: 2248493 | C15: 124652 | D15: Yes | E15: 2248242 | F15: 3076778 | G15: 2800 | H15: 110001 | I15: By Type | J15: M40 | K15: 0 | M15: 0 | N15: 4 | O15: -2001330 | P15: 1.01 m³ | Q15: 2248493 | R15: Yes | S15: 1.008 | T15: No | U15: Vertical | V15: 124652 | W15: 3076778 | X15: 3076778 | Y15: 124652 | Z15: 1E5fPVYML1B9eG4TrHYjm8 | AA15: 230012 | AB15: 2.8 | AC15: 3076778
A16: 3076920 | B16: 2248493 | C16: 124652 | D16: Yes | E16: 2248242 | F16: 3076916 | G16: 2800 | H16: 110001 | I16: By Type | J16: M40 | K16: 0 | M16: 0 | N16: 6.9525 | O16: -2001330 | P16: 1.44 m³ | Q16: 2248493 | R16: Yes | S16: 1.435 | T16: No | U16: Vertical | V16: 124652 | W16: 3076916 | X16: 3076916 | Y16: 124652 | Z16: 0HkMLA0MP5wgflFwXOfFA9 | AA16: 230012 | AB16: 2.8 | AC16: 3076916
... A18: 3077251 | B18: 2248493 | C18: 124652 | D18: Yes | E18: 2248242 | F18: 3077247 | G18: 2800 | H18: 110001 | I18: By Type | J18: M40 | K18: 0 | M18: 0 | N18: 13.91 | O18: -2001330 | P18: 2.49 m³ | Q18: 2248493 | R18: Yes | S18: 2.492 | T18: No | U18: Vertical | V18: 124652 | W18: 3077247 | X18: 3077247 | Y18: 124652 | Z18: 3HF6TA$qL7KxUmTx2qwlF9 | AA18: 230012 | AB18: 2.8 | AC18: 3077247
A19: 3084306 | B19: 2248242 | C19: 124652 | D19: Yes | E19: 2248367 | F19: 2270699 | G19: 5550 | H19: 110001 | I19: By Type | J19: M40 | K19: 0 | L19: P31 | M19: 0 | N19: 6.93 | O19: -2001330 | P19: 1.50 m³ | Q19: 2248242 | R19: Yes | S19: 1.4985 | T19: No | U19: Vertical | V19: 124652 | W19: 2270699 | X19: 2270699 | Y19: 124652 | Z19: 2JGI2Z2THB_wudpkjjxw_6 | AA19: 230012 | AB19: 5.55 | AC19: 2270699
A20: 3084308 | B20: 2248242 | C20: 124652 | D20: Yes | E20: 2248367 | F20: 3113818 | G20: 5550 | H20: 110001 | I20: By Type | J20: M40 | K20: 0 | M20: 0 | N20: 6.345 | O20: -2001330 | P20: 1.33 m³ | Q20: 2248242 | R20: Yes | S20: 1.332 | T20: No | U20: Vertical | V20: 124652 | W20: 3113818 | X20: 3113818 | Y20: 124652 | Z20: 2JGI2Z2THB_wudpkjjxw_0 | AA20: 230012 | AB20: 5.55 | AC20: 3113818
A21: 3084310 | B21: 2248242 | C21: 124652 | D21: Yes | E21: 2248367 | F21: 3072865 | G21: 5550 | H21: 110001 | I21: By Type | J21: M40 | K21: 0 | M21: 0 | N21: 7.615 | O21: -2001330 | P21: 2.22 m³ | Q21: 2248242 | R21: Yes | S21: 2.22 | T21: No | U21: Vertical | V21: 124652 | W21: 3072865 | X21: 3072865 | Y21: 124652 | Z21: 2JGI2Z2THB_wudpkjjxw_2 | AA21: 230012 | AB21: 5.55 | AC21: 3072865
A22: 3084312 | B22: 2248242 | C22: 124652 | D22: Yes | E22: 2248367 | F22: 3080622 | G22: 5550 | H22: 110001 | I22: By Type | J22: M40 | K22: 0 | M22: 0 | N22: 7.5975 | O22: -2001330 | P22: 2.12 m³ | Q22: 2248242 | R22: Yes | S22: 2.1229 | T22: No | U22: Vertical | V22: 124652 | W22: 3080622 | X22: 3080622 | Y22: 124652 | Z22: 2JGI2Z2THB_wudpkjjxw_C | AA22: 230012 | AB22: 5.55 | AC22: 3080622
A23: 3084314 | B23: 2248242 | C23: 124652 | D23: Yes | E23: 2248367 | F23: 3072997 | G23: 5550 | H23: 110001 | I23: By Type | J23: M40 | K23: 0 | M23: 0 | N23: 12.6975 | O23: -2001330 | P23: 2.71 m³ | Q23: 2248242 | R23: Yes | S23: 2.7056 | T23: No | U23: Vertical | V23: 124652 | W23: 3072997 | X23: 3072997 | Y23: 124652 | Z23: 2JGI2Z2THB_wudpkjjxw_E | AA23: 230012 | AB23: 5.55 | AC23: 3072997
A24: 3084316 | B24: 2248242 | C24: 124652 | D24: Yes | E24: 2248367 | F24: 3073021 | G24: 5550 | H24: 110001 | I24: By Type | J24: M40 | K24: 0 | M24: 0 | N24: 2.835 | O24: -2001330 | P24: 0.33 m³ | Q24: 2248242 | R24: Yes | S24: 0.333 | T24: No | U24: Vertical | V24: 124652 | W24: 3073021 | X24: 3073021 | Y24: 124652 | Z24: 2JGI2Z2THB_wudpkjjxw_8 | AA24: 230012 | AB24: 5.55 | AC24: 3073021
A25: 3084318 | B25: 2248242 | C25: 124652 | D25: Yes | E25: 2248367 | F25: 3075811 | G25: 5550 | H25: 110001 | I25: By Type | J25: M40 | K25: 0 | M25: 0 | N25: 12.6975 | O25: -2001330 | P25: 2.71 m³ | Q25: 2248242 | R25: Yes | S25: 2.7056 | T25: No | U25: Vertical | V25: 124652 | W25: 3075811 | X25: 3075811 | Y25: 124652 | Z25: 2JGI2Z2THB_wudpkjjxw_A | AA25: 230012 | AB25: 5.55 | AC25: 3075811
A26: 3084320 | B26: 2248242 | C26: 124652 | D26: Yes | E26: 2248367 | F26: 3075838 | G26: 5550 | H26: 110001 | I26: By Type | J26: M40 | K26: 0 | M26: 0 | N26: 5.3025 | O26: -2001330 | P26: 0.94 m³ | Q26: 2248242 | R26: Yes | S26: 0.9366 | T26: No | U26: Vertical | V26: 124652 | W26: 3075838 | X26: 3075838 | Y26: 124652 | Z26: 2JGI2Z2THB_wudpkjjxw_q | AA26: 230012 | AB26: 5.55 | AC26: 3075838
A27: 3084324 | B27: 2248242 | C27: 124652 | D27: Yes | E27: 2248367 | F27: 3076022 | G27: 5550 | H27: 110001 | I27: By Type | J27: M40 | K27: 0 | M27: 0 | N27: 11.2475 | O27: -2001330 | P27: 2.36 m³ | Q27: 2248242 | R27: Yes | S27: 2.3587 | T27: No | U27: Vertical | V27: 124652 | W27: 3076022 | X27: 3076022 | Y27: 124652 | Z27: 2JGI2Z2THB_wudpkjjxw_m | AA27: 230012 | AB27: 5.55 | AC27: 3076022
A28: 3084326 | B28: 2248242 | C28: 124652 | D28: Yes | E28: 2248367 | F28: 3076222 | G28: 5550 | H28: 110001 | I28: By Type | J28: M40 | K28: 0 | M28: 0 | N28: 5.79 | O28: -2001330 | P28: 1.33 m³ | Q28: 2248242 | R28: Yes | S28: 1.332 | T28: No | U28: Vertical | V28: 124652 | W28: 3076222 | X28: 3076222 | Y28: 124652 | Z28: 2JGI2Z2THB_wudpkjjxw_o | AA28: 230012 | AB28: 5.55 | AC28: 3076222
A29: 3084332 | B29: 2248242 | C29: 124652 | D29: Yes | E29: 2248367 | F29: 3076717 | G29: 5550 | H29: 110001 | I29: By Type | J29: M40 | K29: 0 | M29: 0 | N29: 7.515 | O29: -2001330 | P29: 1.67 m³ | Q29: 2248242 | R29: Yes | S29: 1.665 | T29: No | U29: Vertical | V29: 124652 | W29: 3076717 | X29: 3076717 | Y29: 124652 | Z29: 2JGI2Z2THB_wudpkjjxw_u | AA29: 230012 | AB29: 5.55 | AC29: 3076717
A30: 3084334 | B30: 2248242 | C30: 124652 | D30: Yes | E30: 2248367 | F30: 3076752 | G30: 5550 | H30: 110001 | I30: By Type | J30: M40 | K30: 0 | M30: 0 | N30: 7.575 | O30: -2001330 | P30: 2.00 m³ | Q30: 2248242 | R30: Yes | S30: 1.998 | T30: No | U30: Vertical | V30: 124652 | W30: 3076752 | X30: 3076752 | Y30: 124652 | Z30: 2JGI2Z2THB_wudpkjjxw_w | AA30: 230012 | AB30: 5.55 | AC30: 3076752
A31: 3084336 | B31: 2248242 | C31: 124652 | D31: Yes | E31: 2248367 | F31: 3076778 | G31: 5550 | H31: 110001 | I31: By Type | J31: M40 | K31: 0 | M31: 0 | N31: 7.575 | O31: -2001330 | P31: 2.00 m³ | Q31: 2248242 | R31: Yes | S31: 1.998 | T31: No | U31: Vertical | V31: 124652 | W31: 3076778 | X31: 3076778 | Y31: 124652 | Z31: 2JGI2Z2THB_wudpkjjxw_a | AA31: 230012 | AB31: 5.55 | AC31: 3076778
... A35: 3105514 | B35: 2248242 | C35: 124652 | D35: Yes | E35: 2248367 | F35: 3076639 | G35: 5550 | H35: 110001 | I35: By Type | J35: M40 | K35: 0 | M35: 0 | N35: 20.07 | O35: -2001330 | P35: 6.66 m³ | Q35: 2248242 | R35: Yes | S35: 6.66 | T35: No | U35: Vertical | V35: 124652 | W35: 3076639 | X35: 3076639 | Y35: 124652 | Z35: 0wOuN0$KH13wHCGl$5xo0c | AA35: 230012 | AB35: 5.55 | AC35: 3076639
A36: 3118481 | B36: 2248367 | C36: 124652 | D36: Yes | E36: 2248635 | F36: 2270699 | G36: 2950 | H36: 110001 | I36: By Type | J36: M40 | K36: 0 | L36: P31 | M36: 0 | N36: 3.81 | O36: -2001330 | P36: 0.80 m³ | Q36: 2248367 | R36: Yes | S36: 0.7965 | T36: No | U36: Vertical | V36: 124652 | W36: 2270699 | X36: 2270699 | Y36: 124652 | Z36: 0g26lkPdX4oOgZBW9zmKal | AA36: 230012 | AB36: 2.95 | AC36: 2270699
A37: 3118483 | B37: 2248367 | C37: 124652 | D37: Yes | E37: 2248635 | F37: 3113818 | G37: 2950 | H37: 110001 | I37: By Type | J37: M40 | K37: 0 | M37: 0 | N37: 3.485 | O37: -2001330 | P37: 0.71 m³ | Q37: 2248367 | R37: Yes | S37: 0.708 | T37: No | U37: Vertical | V37: 124652 | W37: 3113818 | X37: 3113818 | Y37: 124652 | Z37: 0g26lkPdX4oOgZBW9zmKaj | AA37: 230012 | AB37: 2.95 | AC37: 3113818
A38: 3118485 | B38: 2248367 | C38: 124652 | D38: Yes | E38: 2248635 | F38: 3072865 | G38: 2950 | H38: 110001 | I38: By Type | J38: M40 | K38: 0 | M38: 0 | N38: 4.235 | O38: -2001330 | P38: 1.18 m³ | Q38: 2248367 | R38: Yes | S38: 1.18 | T38: No | U38: Vertical | V38: 124652 | W38: 3072865 | X38: 3072865 | Y38: 124652 | Z38: 0g26lkPdX4oOgZBW9zmKah | AA38: 230012 | AB38: 2.95 | AC38: 3072865
A39: 3118487 | B39: 2248367 | C39: 124652 | D39: Yes | E39: 2248635 | F39: 3080622 | G39: 2950 | H39: 110001 | I39: By Type | J39: M40 | K39: 0 | M39: 0 | N39: 4.2175 | O39: -2001330 | P39: 1.13 m³ | Q39: 2248367 | R39: Yes | S39: 1.1284 | T39: No | U39: Vertical | V39: 124652 | W39: 3080622 | X39: 3080622 | Y39: 124652 | Z39: 0g26lkPdX4oOgZBW9zmKaf | AA39: 230012 | AB39: 2.95 | AC39: 3080622
A40: 3118489 | B40: 2248367 | C40: 124652 | D40: Yes | E40: 2248635 | F40: 3072997 | G40: 2950 | H40: 110001 | I40: By Type | J40: M40 | K40: 0 | M40: 0 | N40: 6.9775 | O40: -2001330 | P40: 1.44 m³ | Q40: 2248367 | R40: Yes | S40: 1.4381 | T40: No | U40: Vertical | V40: 124652 | W40: 3072997 | X40: 3072997 | Y40: 124652 | Z40: 0g26lkPdX4oOgZBW9zmKad | AA40: 230012 | AB40: 2.95 | AC40: 3072997
A41: 3118491 | B41: 2248367 | C41: 124652 | D41: Yes | E41: 2248635 | F41: 3073021 | G41: 2950 | H41: 110001 | I41: By Type | J41: M40 | K41: 0 | M41: 0 | N41: 1.535 | O41: -2001330 | P41: 0.18 m³ | Q41: 2248367 | R41: Yes | S41: 0.177 | T41: No | U41: Vertical | V41: 124652 | W41: 3073021 | X41: 3073021 | Y41: 124652 | Z41: 0g26lkPdX4oOgZBW9zmKab | AA41: 230012 | AB41: 2.95 | AC41: 3073021
A42: 3118493 | B42: 2248367 | C42: 124652 | D42: Yes | E42: 2248635 | F42: 3075811 | G42: 2950 | H42: 110001 | I42: By Type | J42: M40 | K42: 0 | M42: 0 | N42: 6.9775 | O42: -2001330 | P42: 1.44 m³ | Q42: 2248367 | R42: Yes | S42: 1.4381 | T42: No | U42: Vertical | V42: 124652 | W42: 3075811 | X42: 3075811 | Y42: 124652 | Z42: 0g26lkPdX4oOgZBW9zmKaZ | AA42: 230012 | AB42: 2.95 | AC42: 3075811
A43: 3118495 | B43: 2248367 | C43: 124652 | D43: Yes | E43: 2248635 | F43: 3075838 | G43: 2950 | H43: 110001 | I43: By Type | J43: M40 | K43: 0 | M43: 0 | N43: 2.8975 | O43: -2001330 | P43: 0.50 m³ | Q43: 2248367 | R43: Yes | S43: 0.4978 | T43: No | U43: Vertical | V43: 124652 | W43: 3075838 | X43: 3075838 | Y43: 124652 | Z43: 0g26lkPdX4oOgZBW9zmKaX | AA43: 230012 | AB43: 2.95 | AC43: 3075838
A44: 3118499 | B44: 2248367 | C44: 124652 | D44: Yes | E44: 2248635 | F44: 3076022 | G44: 2950 | H44: 110001 | I44: By Type | J44: M40 | K44: 0 | M44: 0 | N44: 6.1775 | O44: -2001330 | P44: 1.25 m³ | Q44: 2248367 | R44: Yes | S44: 1.2537 | T44: No | U44: Vertical | V44: 124652 | W44: 3076022 | X44: 3076022 | Y44: 124652 | Z44: 0g26lkPdX4oOgZBW9zmKaT | AA44: 230012 | AB44: 2.95 | AC44: 3076022
...

Sheet Slab
A1: Element ID | B1: Level | C1: Rebar Cover - Top Face | D1: Elevation at Top Survey | E1: Height Offset From Level | F1: Related to Mass | G1: Structural | H1: Type | I1: Elevation at Top | J1: Length | K1: Phase Created | L1: Elevation at Bottom | M1: Elevation at Top Core | N1: Export to IFC | O1: Perimeter | P1: GRADE OF CONCRETE | Q1: ID_UNMT | R1: Width | S1: Qty: Area (m2) | T1: Area | U1: Category | V1: Volume | W1: Thickness | X1: Qty: Volume (m3) | Y1: Has Association | Z1: Core Thickness | AA1: Elevation at Bottom Core | AB1: Elevation at Bottom Survey | AC1: Rebar Cover - Other Faces | AD1: Type Id | AE1: Family | AF1: Rebar Cover - Bottom Face | AG1: IfcGUID | AH1: Family and Type
A2: 3070305 | B2: 2248493 | C2: 3178027 | D2: -2350 | E2: 0 | F2: No | G2: Yes | H2: 3070326 | I2: -2350 | J2: 1500 | K2: 110001 | L2: -2950 | M2: -2350 | N2: By Type | O2: 7000 | P2: M40 | Q2: F1 | R2: 2000 | S2: 3 | T2: 3 m² | U2: -2001300 | V2: 1.80 m³ | W2: 600 | X2: 1.8 | Y2: No | Z2: 600 | AA2: -2950 | AB2: -2950 | AC2: 3178027 | AD2: 3070326 | AE2: 3070326 | AG2: 33AYsgylX80BV2OFfKznor | AH2: 3070326
A3: 3070393 | B3: 2248493 | C3: 124652 | D3: -2950 | E3: -600 | F3: No | G3: Yes | H3: 2255647 | I3: -2950 | J3: 1700 | K3: 110001 | L3: -3050 | M3: -2950 | N3: By Type | O3: 7800 | P3: M10 | Q3: PCC_FOOTING | R3: 2200 | S3: 3.74 | T3: 4 m² | U3: -2001300 | V3: 0.37 m³ | W3: 100 | X3: 0.374 | Y3: No | Z3: 100 | AA3: -3050 | AB3: -3050 | AC3: 124652 | AD3: 2255647 | AE3: 2255647 | AF3: 124652 | AG3: 33AYsgylX80BV2OFfKznnj | AH3: 2255647
A4: 3070773 | B4: 2248493 | C4: 3178027 | D4: -2350 | E4: 0 | F4: No | G4: Yes | H4: 3070326 | I4: -2350 | J4: 1500 | K4: 110001 | L4: -2950 | M4: -2350 | N4: By Type | O4: 7000 | P4: M40 | Q4: F1 | R4: 2000 | S4: 3 | T4: 3 m² | U4: -2001300 | V4: 1.80 m³ | W4: 600 | X4: 1.8 | Y4: No | Z4: 600 | AA4: -2950 | AB4: -2950 | AC4: 3178027 | AD4: 3070326 | AE4: 3070326 | AG4: 1OIgpuqiH33Qs8VR23YRZc | AH4: 3070326
A5: 3070782 | B5: 2248493 | C5: 124652 | D5: -2950 | E5: -600 | F5: No | G5: Yes | H5: 2255647 | I5: -2950 | J5: 1700 | K5: 110001 | L5: -3050 | M5: -2950 | N5: By Type | O5: 7800 | P5: M10 | Q5: PCC_FOOTING | R5: 2200 | S5: 3.74 | T5: 4 m² | U5: -2001300 | V5: 0.37 m³ | W5: 100 | X5: 0.374 | Y5: No | Z5: 100 | AA5: -3050 | AB5: -3050 | AC5: 124652 | AD5: 2255647 | AE5: 2255647 | AF5: 124652 | AG5: 1OIgpuqiH33Qs8VR23YRZj | AH5: 2255647
A6: 3070818 | B6: 2248493 | C6: 3178027 | D6: -2350 | E6: 0 | F6: No | G6: Yes | H6: 3071073 | I6: -2350 | J6: 2200 | K6: 110001 | L6: -3050 | M6: -2350 | N6: By Type | O6: 8000 | P6: M40 | Q6: F2 | R6: 1800 | S6: 3.96 | T6: 4 m² | U6: -2001300 | V6: 2.77 m³ | W6: 700 | X6: 2.772 | Y6: No | Z6: 700 | AA6: -3050 | AB6: -3050 | AC6: 3178027 | AD6: 3071073 | AE6: 3071073 | AG6: 3_y0Jm7LL5Uf8xXWt_c0b1 | AH6: 3071073
A7: 3070827 | B7: 2248493 | C7: 124652 | D7: -3050 | E7: -700 | F7: No | G7: Yes | H7: 2255647 | I7: -3050 | J7: 2400 | K7: 110001 | L7: -3150 | M7: -3050 | N7: By Type | O7: 8800 | P7: M10 | Q7: PCC_FOOTING | R7: 2000 | S7: 4.8 | T7: 5 m² | U7: -2001300 | V7: 0.48 m³ | W7: 100 | X7: 0.48 | Y7: No | Z7: 100 | AA7: -3150 | AB7: -3150 | AC7: 124652 | AD7: 2255647 | AE7: 2255647 | AF7: 124652 | AG7: 3_y0Jm7LL5Uf8xXWt_c0b8 | AH7: 2255647
A8: 3070960 | B8: 2248493 | C8: 3178027 | D8: -2350 | E8: 0 | F8: No | G8: Yes | H8: 3071073 | I8: -2350 | J8: 2200 | K8: 110001 | L8: -3050 | M8: -2350 | N8: By Type | O8: 8000 | P8: M40 | Q8: F2 | R8: 1800 | S8: 3.96 | T8: 4 m² | U8: -2001300 | V8: 2.77 m³ | W8: 700 | X8: 2.772 | Y8: No | Z8: 700 | AA8: -3050 | AB8: -3050 | AC8: 3178027 | AD8: 3071073 | AE8: 3071073 | AG8: 2vYX391Bf25OBSrHEK9sy$ | AH8: 3071073
A9: 3070969 | B9: 2248493 | C9: 124652 | D9: -3050 | E9: -700 | F9: No | G9: Yes | H9: 2255647 | I9: -3050 | J9: 2400 | K9: 110001 | L9: -3150 | M9: -3050 | N9: By Type | O9: 8800 | P9: M10 | Q9: PCC_FOOTING | R9: 2000 | S9: 4.8 | T9: 5 m² | U9: -2001300 | V9: 0.48 m³ | W9: 100 | X9: 0.48 | Y9: No | Z9: 100 | AA9: -3150 | AB9: -3150 | AC9: 124652 | AD9: 2255647 | AE9: 2255647 | AF9: 124652 | AG9: 2vYX391Bf25OBSrHEK9sys | AH9: 2255647
A10: 3071149 | B10: 2248493 | C10: 3178027 | D10: -2350 | E10: 0 | F10: No | G10: Yes | H10: 3071090 | I10: -2350 | J10: 2700 | K10: 110001 | L10: -3050 | M10: -2350 | N10: By Type | O10: 8000 | P10: M40 | Q10: F3 | R10: 1300 | S10: 3.51 | T10: 4 m² | U10: -2001300 | V10: 2.46 m³ | W10: 700 | X10: 2.457 | Y10: No | Z10: 700 | AA10: -3050 | AB10: -3050 | AC10: 3178027 | AD10: 3071090 | AE10: 3071090 | AG10: 0pBnFJmFzFEwLCxY_KwjGT | AH10: 3071090
A11: 3071158 | B11: 2248493 | C11: 124652 | D11: -3050 | E11: -700 | F11: No | G11: Yes | H11: 2255647 | I11: -3050 | J11: 2900 | K11: 110001 | L11: -3150 | M11: -3050 | N11: By Type | O11: 8800 | P11: M10 | Q11: PCC_FOOTING | R11: 1500 | S11: 4.35 | T11: 4 m² | U11: -2001300 | V11: 0.44 m³ | W11: 100 | X11: 0.435 | Y11: No | Z11: 100 | AA11: -3150 | AB11: -3150 | AC11: 124652 | AD11: 2255647 | AE11: 2255647 | AF11: 124652 | AG11: 0pBnFJmFzFEwLCxY_KwjG6 | AH11: 2255647
A12: 3071322 | B12: 2248493 | C12: 3178027 | D12: -2350 | E12: 0 | F12: No | G12: Yes | H12: 3175964 | I12: -2350 | J12: 1300 | K12: 110001 | L12: -2850 | M12: -2350 | N12: By Type | O12: 6200 | P12: M40 | Q12: F5 | R12: 1800 | S12: 2.34 | T12: 2 m² | U12: -2001300 | V12: 1.17 m³ | W12: 500 | X12: 1.17 | Y12: No | Z12: 500 | AA12: -2850 | AB12: -2850 | AC12: 3178027 | AD12: 3175964 | AE12: 3175964 | AG12: 2tUNbxU1T0IBvn6Zylc4PG | AH12: 3175964
A13: 3071331 | B13: 2248493 | C13: 124652 | D13: -2850 | E13: -500 | F13: No | G13: Yes | H13: 2255647 | I13: -2850 | J13: 1500 | K13: 110001 | L13: -2950 | M13: -2850 | N13: By Type | O13: 7000 | P13: M10 | Q13: PCC_FOOTING | R13: 2000 | S13: 3 | T13: 3 m² | U13: -2001300 | V13: 0.30 m³ | W13: 100 | X13: 0.3 | Y13: No | Z13: 100 | AA13: -2950 | AB13: -2950 | AC13: 124652 | AD13: 2255647 | AE13: 2255647 | AF13: 124652 | AG13: 2tUNbxU1T0IBvn6Zylc4Pf | AH13: 2255647
A14: 3071454 | B14: 2248493 | C14: 3178027 | D14: -2350 | E14: 0 | F14: No | G14: Yes | H14: 3071368 | I14: -2350 | J14: 7550 | K14: 110001 | L14: -3100 | M14: -2350 | N14: By Type | O14: 32600 | P14: M40 | Q14: CF1 | R14: 8750 | S14: 66.0625 | T14: 66 m² | U14: -2001300 | V14: 49.55 m³ | W14: 750 | X14: 49.5469 | Y14: No | Z14: 750 | AA14: -3100 | AB14: -3100 | AC14: 3178027 | AD14: 3071368 | AE14: 3071368 | AG14: 0yn1G3deX64RIHl7h1zcMy | AH14: 3071368
A15: 3071463 | B15: 2248493 | C15: 124652 | D15: -3100 | E15: -750 | F15: No | G15: Yes | H15: 2255647 | I15: -3100 | J15: 7750 | K15: 110001 | L15: -3200 | M15: -3100 | N15: By Type | O15: 33400 | P15: M10 | Q15: PCC_FOOTING | R15: 8950 | S15: 69.3625 | T15: 69 m² | U15: -2001300 | V15: 6.94 m³ | W15: 100 | X15: 6.9363 | Y15: No | Z15: 100 | AA15: -3200 | AB15: -3200 | AC15: 124652 | AD15: 2255647 | AE15: 2255647 | AF15: 124652 | AG15: 0yn1G3deX64RIHl7h1zcM5 | AH15: 2255647
A16: 3071667 | B16: 2248493 | C16: 3178027 | D16: -2350 | E16: 0 | F16: No | G16: Yes | H16: 3071385 | I16: -2350 | J16: 4000 | K16: 110001 | L16: -3100 | M16: -2350 | N16: By Type | O16: 24600 | P16: M40 | Q16: CF2 | R16: 8300 | S16: 28.9418 | T16: 29 m² | U16: -2001300 | V16: 21.71 m³ | W16: 750 | X16: 21.7063 | Y16: No | Z16: 750 | AA16: -3100 | AB16: -3100 | AC16: 3178027 | AD16: 3071385 | AE16: 3071385 | AG16: 1iNhjbtjT27ezT3D1vCLgG | AH16: 3071385
A17: 3071676 | B17: 2248493 | C17: 124652 | D17: -3100 | E17: -750 | F17: No | G17: Yes | H17: 2255647 | I17: -3100 | J17: 4200 | K17: 110001 | L17: -3200 | M17: -3100 | N17: By Type | O17: 25400 | P17: M10 | Q17: PCC_FOOTING | R17: 8500 | S17: 31.4418 | T17: 31 m² | U17: -2001300 | V17: 3.14 m³ | W17: 100 | X17: 3.1442 | Y17: No | Z17: 100 | AA17: -3200 | AB17: -3200 | AC17: 124652 | AD17: 2255647 | AE17: 2255647 | AF17: 124652 | AG17: 1iNhjbtjT27ezT3D1vCLgV | AH17: 2255647
A18: 3087101 | B18: 2248242 | C18: 3178026 | D18: 450 | E18: 0 | F18: No | G18: Yes | H18: 2432663 | I18: 450 | J18: 3850 | K18: 110001 | L18: 300 | M18: 450 | N18: By Type | O18: 15600 | P18: M30 | Q18: GS | R18: 3950 | S18: 15.2075 | T18: 15 m² | U18: -2001300 | V18: 2.28 m³ | W18: 150 | X18: 2.2811 | Y18: No | Z18: 150 | AA18: 300 | AB18: 300 | AC18: 3178026 | AD18: 2432663 | AE18: 2432663 | AF18: 3178026 | AG18: 1ndm0CiUv2$BFHfN_6Vb0K | AH18: 2432663
A19: 3087176 | B19: 2248242 | C19: 3178026 | D19: 450 | E19: 0 | F19: No | G19: Yes | H19: 2432663 | I19: 450 | J19: 4500 | K19: 110001 | L19: 300 | M19: 450 | N19: By Type | O19: 11800 | P19: M30 | Q19: GS | R19: 1400 | S19: 5.882 | T19: 6 m² | U19: -2001300 | V19: 0.88 m³ | W19: 150 | X19: 0.8823 | Y19: No | Z19: 150 | AA19: 300 | AB19: 300 | AC19: 3178026 | AD19: 2432663 | AE19: 2432663 | AF19: 3178026 | AG19: 1ndm0CiUv2$BFHfN_6Vb6X | AH19: 2432663
A20: 3087547 | B20: 2248242 | C20: 3178026 | D20: 450 | E20: 0 | F20: No | G20: Yes | H20: 2432663 | I20: 450 | J20: 7300 | K20: 110001 | L20: 300 | M20: 450 | N20: By Type | O20: 19200 | P20: M30 | Q20: GS | R20: 2300 | S20: 16.79 | T20: 17 m² | U20: -2001300 | V20: 2.52 m³ | W20: 150 | X20: 2.5185 | Y20: No | Z20: 150 | AA20: 300 | AB20: 300 | AC20: 3178026 | AD20: 2432663 | AE20: 2432663 | AF20: 3178026 | AG20: 2s4LoatorAAwedE__QUFe9 | AH20: 2432663
A21: 3087577 | B21: 2248242 | C21: 3178026 | D21: 450 | E21: 0 | F21: No | G21: Yes | H21: 2432663 | I21: 450 | J21: 1100 | K21: 110001 | L21: 300 | M21: 450 | N21: By Type | O21: 5000 | P21: M30 | Q21: GS | R21: 1400 | S21: 1.54 | T21: 2 m² | U21: -2001300 | V21: 0.23 m³ | W21: 150 | X21: 0.231 | Y21: No | Z21: 150 | AA21: 300 | AB21: 300 | AC21: 3178026 | AD21: 2432663 | AE21: 2432663 | AF21: 3178026 | AG21: 2s4LoatorAAwedE__QUFfh | AH21: 2432663
A22: 3087615 | B22: 2248242 | C22: 3178026 | D22: 450 | E22: 0 | F22: No | G22: Yes | H22: 2432663 | I22: 450 | J22: 1800 | K22: 110001 | L22: 300 | M22: 450 | N22: By Type | O22: 9100 | P22: M30 | Q22: GS | R22: 2750 | S22: 4.95 | T22: 5 m² | U22: -2001300 | V22: 0.74 m³ | W22: 150 | X22: 0.7425 | Y22: No | Z22: 150 | AA22: 300 | AB22: 300 | AC22: 3178026 | AD22: 2432663 | AE22: 2432663 | AF22: 3178026 | AG22: 2s4LoatorAAwedE__QUFfD | AH22: 2432663
A23: 3087646 | B23: 2248242 | C23: 3178026 | D23: 450 | E23: 0 | F23: No | G23: Yes | H23: 2432663 | I23: 450 | J23: 3750 | K23: 110001 | L23: 300 | M23: 450 | N23: By Type | O23: 10100 | P23: M30 | Q23: GS | R23: 1300 | S23: 4.875 | T23: 5 m² | U23: -2001300 | V23: 0.73 m³ | W23: 150 | X23: 0.7312 | Y23: No | Z23: 150 | AA23: 300 | AB23: 300 | AC23: 3178026 | AD23: 2432663 | AE23: 2432663 | AF23: 3178026 | AG23: 2s4LoatorAAwedE__QUFki | AH23: 2432663
A24: 3109330 | B24: 2248367 | C24: 3178026 | D24: 6000 | E24: 0 | F24: No | G24: Yes | H24: 3109334 | I24: 6000 | J24: 3000 | K24: 110001 | L24: 5875 | M24: 6000 | N24: By Type | O24: 11900 | P24: M30 | Q24: S1 | R24: 2950 | S24: 8.625 | T24: 9 m² | U24: -2001300 | V24: 1.08 m³ | W24: 125 | X24: 1.0781 | Y24: No | Z24: 125 | AA24: 5875 | AB24: 5875 | AC24: 3178026 | AD24: 3109334 | AE24: 3109334 | AF24: 3178026 | AG24: 0UylgE0A9EXxC6WjIwqD9C | AH24: 3109334
A25: 3109385 | B25: 2248367 | C25: 3178026 | D25: 6000 | E25: 0 | F25: No | G25: Yes | H25: 3109334 | I25: 6000 | J25: 3000 | K25: 110001 | L25: 5875 | M25: 6000 | N25: By Type | O25: 13100 | P25: M30 | Q25: S1 | R25: 3400 | S25: 9.83 | T25: 10 m² | U25: -2001300 | V25: 1.23 m³ | W25: 125 | X25: 1.2288 | Y25: No | Z25: 125 | AA25: 5875 | AB25: 5875 | AC25: 3178026 | AD25: 3109334 | AE25: 3109334 | AF25: 3178026 | AG25: 27y$lZUv133P$f_o6eKHOJ | AH25: 3109334
A26: 3109449 | B26: 2248367 | C26: 3178026 | D26: 6000 | E26: 0 | F26: No | G26: Yes | H26: 3109334 | I26: 6000 | J26: 1150 | K26: 110001 | L26: 5875 | M26: 6000 | N26: By Type | O26: 4600 | P26: M30 | Q26: S2 | R26: 1150 | S26: 1.3225 | T26: 1 m² | U26: -2001300 | V26: 0.17 m³ | W26: 125 | X26: 0.1653 | Y26: No | Z26: 125 | AA26: 5875 | AB26: 5875 | AC26: 3178026 | AD26: 3109334 | AE26: 3109334 | AF26: 3178026 | AG26: 27y$lZUv133P$f_o6eKHPJ | AH26: 3109334
A27: 3109467 | B27: 2248367 | C27: 3178026 | D27: 5800 | E27: -200 | F27: No | G27: Yes | H27: 3109334 | I27: 5800 | J27: 1850 | K27: 110001 | L27: 5675 | M27: 5800 | N27: By Type | O27: 6000 | P27: M30 | Q27: S3 | R27: 1150 | S27: 2.1275 | T27: 2 m² | U27: -2001300 | V27: 0.27 m³ | W27: 125 | X27: 0.2659 | Y27: No | Z27: 125 | AA27: 5675 | AB27: 5675 | AC27: 3178026 | AD27: 3109334 | AE27: 3109334 | AF27: 3178026 | AG27: 27y$lZUv133P$f_o6eKHP1 | AH27: 3109334
A28: 3112954 | B28: 2248367 | C28: 3178026 | D28: 5875 | E28: -125 | F28: No | G28: Yes | H28: 3112958 | I28: 5875 | J28: 125 | K28: 110001 | L28: 5675 | M28: 5875 | N28: By Type | O28: 2550 | P28: M30 | Q28: FOLD 200 THK | R28: 1150 | S28: 0.1437 | T28: 0 m² | U28: -2001300 | V28: 0.03 m³ | W28: 200 | X28: 0.0287 | Y28: No | Z28: 200 | AA28: 5675 | AB28: 5675 | AC28: 3178026 | AD28: 3112958 | AE28: 3112958 | AF28: 3178026 | AG28: 2rDPgXFQP2mOAbXe12L2W3 | AH28: 3112958
... A86: 3120416 | B86: 2248635 | C86: 3178026 | D86: 8950 | E86: 0 | F86: No | G86: Yes | H86: 3109334 | I86: 8950 | J86: 3100 | K86: 110001 | L86: 8825 | M86: 8950 | N86: By Type | O86: 14200 | P86: M30 | Q86: S1 | R86: 4000 | S86: 12.33 | T86: 12 m² | U86: -2001300 | V86: 1.54 m³ | W86: 125 | X86: 1.5412 | Y86: No | Z86: 125 | AA86: 8825 | AB86: 8825 | AC86: 3178026 | AD86: 3109334 | AE86: 3109334 | AF86: 3178026 | AG86: 04OWjS4_XFfvTcATeW4rU$ | AH86: 3109334
A87: 3120425 | B87: 2248635 | C87: 3178026 | D87: 8950 | E87: 0 | F87: No | G87: Yes | H87: 3113164 | I87: 8950 | J87: 3550 | K87: 110001 | L87: 8800 | M87: 8950 | N87: By Type | O87: 19220 | P87: M30 | Q87: S6 | R87: 6060 | S87: 21.2335 | T87: 21 m² | U87: -2001300 | V87: 3.19 m³ | W87: 150 | X87: 3.185 | Y87: No | Z87: 150 | AA87: 8800 | AB87: 8800 | AD87: 3113164 | AE87: 3113164 | AF87: 3178026 | AG87: 04OWjS4_XFfvTcATeW4rUs | AH87: 3113164
A88: 3120443 | B88: 2248635 | C88: 3178026 | D88: 8950 | E88: 0 | F88: No | G88: Yes | H88: 3113164 | I88: 8950 | J88: 5200 | K88: 110001 | L88: 8800 | M88: 8950 | N88: By Type | O88: 20600 | P88: M30 | Q88: S6 | R88: 5000 | S88: 21.21 | T88: 21 m² | U88: -2001300 | V88: 3.18 m³ | W88: 150 | X88: 3.1815 | Y88: No | Z88: 150 | AA88: 8800 | AB88: 8800 | AC88: 3178026 | AD88: 3113164 | AE88: 3113164 | AF88: 3178026 | AG88: 04OWjS4_XFfvTcATeW4rUa | AH88: 3113164
A89: 3120452 | B89: 2248635 | C89: 3178026 | D89: 8750 | E89: -200 | F89: No | G89: Yes | H89: 3109334 | I89: 8750 | J89: 750 | K89: 110001 | L89: 8625 | M89: 8750 | N89: By Type | O89: 8000 | P89: M30 | Q89: S8 | R89: 3250 | S89: 2.4375 | T89: 2 m² | U89: -2001300 | V89: 0.30 m³ | W89: 125 | X89: 0.3047 | Y89: No | Z89: 125 | AA89: 8625 | AB89: 8625 | AC89: 3178026 | AD89: 3109334 | AE89: 3109334 | AF89: 3178026 | AG89: 04OWjS4_XFfvTcATeW4rVR | AH89: 3109334
A90: 3120478 | B90: 2248635 | C90: 3178026 | D90: 8500 | E90: -450 | F90: No | G90: Yes | H90: 3113132 | I90: 8500 | J90: 750 | K90: 110001 | L90: 8400 | M90: 8500 | N90: By Type | O90: 14620 | P90: M30 | Q90: S9 | R90: 6560 | S90: 4.92 | T90: 5 m² | U90: -2001300 | V90: 0.49 m³ | W90: 100 | X90: 0.492 | Y90: No | Z90: 100 | AA90: 8400 | AB90: 8400 | AC90: 3178026 | AD90: 3113132 | AE90: 3113132 | AF90: 3178026 | AG90: 04OWjS4_XFfvTcATeW4rV1 | AH90: 3113132
A91: 3120487 | B91: 2248635 | C91: 3178026 | D91: 8500 | E91: -450 | F91: No | G91: Yes | H91: 3113132 | I91: 8500 | J91: 750 | K91: 110001 | L91: 8400 | M91: 8500 | N91: By Type | O91: 10000 | P91: M30 | Q91: S9 | R91: 4250 | S91: 3.1875 | T91: 3 m² | U91: -2001300 | V91: 0.32 m³ | W91: 100 | X91: 0.3187 | Y91: No | Z91: 100 | AA91: 8400 | AB91: 8400 | AC91: 3178026 | AD91: 3113132 | AE91: 3113132 | AF91: 3178026 | AG91: 04OWjS4_XFfvTcATeW4rVu | AH91: 3113132
A92: 3120496 | B92: 2248635 | C92: 3178026 | D92: 8500 | E92: -450 | F92: No | G92: Yes | H92: 3113132 | I92: 8500 | J92: 600 | K92: 110001 | L92: 8400 | M92: 8500 | N92: By Type | O92: 16160 | P92: M30 | Q92: S9 | R92: 7480 | S92: 4.488 | T92: 4 m² | U92: -2001300 | V92: 0.45 m³ | W92: 100 | X92: 0.4488 | Y92: No | Z92: 100 | AA92: 8400 | AB92: 8400 | AC92: 3178026 | AD92: 3113132 | AE92: 3113132 | AF92: 3178026 | AG92: 04OWjS4_XFfvTcATeW4rVl | AH92: 3113132
A93: 3120507 | B93: 2248635 | C93: 3178026 | D93: 8500 | E93: -450 | F93: No | G93: Yes | H93: 3113132 | I93: 8500 | J93: 600 | K93: 110001 | L93: 8400 | M93: 8500 | N93: By Type | O93: 12600 | P93: M30 | Q93: S9 | R93: 5700 | S93: 3.42 | T93: 3 m² | U93: -2001300 | V93: 0.34 m³ | W93: 100 | X93: 0.342 | Y93: No | Z93: 100 | AA93: 8400 | AB93: 8400 | AC93: 3178026 | AD93: 3113132 | AE93: 3113132 | AF93: 3178026 | AG93: 04OWjS4_XFfvTcATeW4rVa | AH93: 3113132
A94: 3120516 | B94: 2248635 | C94: 3178026 | D94: 8500 | E94: -450 | F94: No | G94: Yes | H94: 3113132 | I94: 8500 | J94: 600 | K94: 110001 | L94: 8400 | M94: 8500 | N94: By Type | O94: 2710 | P94: M30 | Q94: S9 | R94: 755 | S94: 0.453 | T94: 0 m² | U94: -2001300 | V94: 0.05 m³ | W94: 100 | X94: 0.0453 | Y94: No | Z94: 100 | AA94: 8400 | AB94: 8400 | AC94: 3178026 | AD94: 3113132 | AE94: 3113132 | AF94: 3178026 | AG94: 04OWjS4_XFfvTcATeW4rSR | AH94: 3113132
A95: 3121237 | B95: 2248635 | C95: 3178026 | D95: 8750 | E95: -200 | F95: No | G95: Yes | H95: 3109334 | I95: 8750 | J95: 1850 | K95: 110001 | L95: 8625 | M95: 8750 | N95: By Type | O95: 6100 | P95: M30 | Q95: S3 | R95: 1200 | S95: 2.22 | T95: 2 m² | U95: -2001300 | V95: 0.28 m³ | W95: 125 | X95: 0.2775 | Y95: No | Z95: 125 | AA95: 8625 | AB95: 8625 | AC95: 3178026 | AD95: 3109334 | AE95: 3109334 | AF95: 3178026 | AG95: 3E1pXqZUjAQuCbu1RRb8Ss | AH95: 3109334
A96: 3121246 | B96: 2248635 | D96: 8825 | E96: -125 | F96: No | G96: Yes | H96: 3112958 | I96: 8825 | J96: 150 | K96: 110001 | L96: 8625 | M96: 8825 | N96: By Type | O96: 2700 | P96: M30 | Q96: FOLD 200 THK | R96: 1200 | S96: 0.18 | T96: 0 m² | U96: -2001300 | V96: 0.04 m³ | W96: 200 | X96: 0.036 | Y96: No | Z96: 200 | AA96: 8625 | AB96: 8625 | AC96: 3178026 | AD96: 3112958 | AE96: 3112958 | AF96: 3178026 | AG96: 3E1pXqZUjAQuCbu1RRb8Sz | AH96: 3112958
A97: 3127253 | B97: 2248691 | C97: 3178026 | D97: 11900 | E97: 0 | F97: No | G97: Yes | H97: 3109334 | I97: 11900 | J97: 3000 | K97: 110001 | L97: 11775 | M97: 11900 | N97: By Type | O97: 11800 | P97: M30 | Q97: S1 | R97: 2900 | S97: 8.475 | T97: 8 m² | U97: -2001300 | V97: 1.06 m³ | W97: 125 | X97: 1.0594 | Y97: No | Z97: 125 | AA97: 11775 | AB97: 11775 | AC97: 3178026 | AD97: 3109334 | AE97: 3109334 | AF97: 3178026 | AG97: 3Efj1PFo5FlAk9KG3QmchX | AH97: 3109334
...

Sheet Foundation
A1: Element ID | B1: Level | C1: Rebar Cover - Top Face | D1: Elevation at Top Survey | E1: Height Offset From Level | F1: Related to Mass | G1: Structural | H1: Type | I1: Elevation at Top | J1: Length | K1: Phase Created | L1: Elevation at Bottom | M1: Elevation at Top Core | N1: Export to IFC | O1: Perimeter | P1: GRADE OF CONCRETE | Q1: ID_UNMT | R1: Width | S1: Qty: Area (m2) | T1: Area | U1: Category | V1: Volume | W1: Thickness | X1: Qty: Volume (m3) | Y1: Has Association | Z1: Core Thickness | AA1: Elevation at Bottom Core | AB1: Elevation at Bottom Survey | AC1: Rebar Cover - Other Faces | AD1: Type Id | AE1: Family | AF1: Rebar Cover - Bottom Face | AG1: IfcGUID | AH1: Family and Type
A2: 3070393 | B2: 2248493 | C2: 124652 | D2: -2950 | E2: -600 | F2: No | G2: Yes | H2: 2255647 | I2: -2950 | J2: 1700 | K2: 110001 | L2: -3050 | M2: -2950 | N2: By Type | O2: 7800 | P2: M10 | Q2: PCC_FOOTING | R2: 2200 | S2: 3.74 | T2: 4 m² | U2: -2001300 | V2: 0.37 m³ | W2: 100 | X2: 0.374 | Y2: No | Z2: 100 | AA2: -3050 | AB2: -3050 | AC2: 124652 | AD2: 2255647 | AE2: 2255647 | AF2: 124652 | AG2: 33AYsgylX80BV2OFfKznnj | AH2: 2255647
A3: 3070782 | B3: 2248493 | C3: 124652 | D3: -2950 | E3: -600 | F3: No | G3: Yes | H3: 2255647 | I3: -2950 | J3: 1700 | K3: 110001 | L3: -3050 | M3: -2950 | N3: By Type | O3: 7800 | P3: M10 | Q3: PCC_FOOTING | R3: 2200 | S3: 3.74 | T3: 4 m² | U3: -2001300 | V3: 0.37 m³ | W3: 100 | X3: 0.374 | Y3: No | Z3: 100 | AA3: -3050 | AB3: -3050 | AC3: 124652 | AD3: 2255647 | AE3: 2255647 | AF3: 124652 | AG3: 1OIgpuqiH33Qs8VR23YRZj | AH3: 2255647
A4: 3070827 | B4: 2248493 | C4: 124652 | D4: -3050 | E4: -700 | F4: No | G4: Yes | H4: 2255647 | I4: -3050 | J4: 2400 | K4: 110001 | L4: -3150 | M4: -3050 | N4: By Type | O4: 8800 | P4: M10 | Q4: PCC_FOOTING | R4: 2000 | S4: 4.8 | T4: 5 m² | U4: -2001300 | V4: 0.48 m³ | W4: 100 | X4: 0.48 | Y4: No | Z4: 100 | AA4: -3150 | AB4: -3150 | AC4: 124652 | AD4: 2255647 | AE4: 2255647 | AF4: 124652 | AG4: 3_y0Jm7LL5Uf8xXWt_c0b8 | AH4: 2255647
A5: 3070969 | B5: 2248493 | C5: 124652 | D5: -3050 | E5: -700 | F5: No | G5: Yes | H5: 2255647 | I5: -3050 | J5: 2400 | K5: 110001 | L5: -3150 | M5: -3050 | N5: By Type | O5: 8800 | P5: M10 | Q5: PCC_FOOTING | R5: 2000 | S5: 4.8 | T5: 5 m² | U5: -2001300 | V5: 0.48 m³ | W5: 100 | X5: 0.48 | Y5: No | Z5: 100 | AA5: -3150 | AB5: -3150 | AC5: 124652 | AD5: 2255647 | AE5: 2255647 | AF5: 124652 | AG5: 2vYX391Bf25OBSrHEK9sys | AH5: 2255647
