Workbook

Sheet Beam
A1: Element ID | B1: Start Level Offset | C1: y Justification | D1: z Justification | E1: Qty: Area (m2) | F1: Rebar Cover - Other Faces | G1: Work Plane | H1: GRADE OF CONCRETE | I1: BEAM WIDTH | J1: Cut Length | K1: Type Id | L1: Length | M1: Qty: Volume (m3) | N1: z Offset Value | O1: Rebar Cover - Bottom Face | P1: Phase Created | Q1: Type | R1: Volume | S1: Family | T1: Reference Level Elevation | U1: Category | V1: Rebar Cover - Top Face | W1: Elevation at Top | X1: BEAM DEPTH | Y1: Has Association | Z1: Structural Usage | AA1: y Offset Value | AB1: Qty: Length (m) | AC1: End Level Offset | AD1: Qty: Count | AE1: Structural Material | AF1: ID_UNMT | AG1: Reference Level | AH1: Join Status | AI1: Orientation | AJ1: Elevation at Bottom | AK1: Family and Type | AL1: IfcGUID | AM1: ROOM NO. | AN1: yz Justification | AO1: Export to IFC | AP1: Cross-Section Rotation
A2: 3079902 | B2: 0 | C2: Left | D2: Top | E2: 2.4575 | G2: Level : 03 PLINTH LEVEL | H2: M30 | I2: 250 | J2: 2900 | K2: 3079709 | L2: 2900 | M2: 0.3987 | N2: 0 | O2: BEAM <25 mm> | P2: New Construction | Q2: B(a) - 250 X 550 | R2: 0.40 m³ | S2: Concrete-Rectangular Beam | T2: 450 | U2: Structural Framing | V2: BEAM <25 mm> | W2: 450 | X2: 550 | Y2: No | Z2: Other | AA2: 0 | AB2: 2.9 | AC2: 0 | AD2: 1 | AE2: RCC_BEAM | AF2: B10 | AG2: 03 PLINTH LEVEL | AH2: One or two joins disabled | AI2: Normal | AJ2: -100 | AK2: Concrete-Rectangular Beam: B(a) - 250 X 550 | AL2: 0sZlodXlT3tverCRqGTnXq | AN2: Uniform | AO2: By Type | AP2: 0.00°
A3: 3080849 | B3: 0 | C3: Left | D3: Top | E3: 2.0375 | G3: Level : 03 PLINTH LEVEL | H3: M30 | I3: 250 | J3: 2375 | K3: 3079709 | L3: 2375 | M3: 0.3266 | N3: 0 | O3: BEAM <25 mm> | P3: New Construction | Q3: B(a) - 250 X 550 | R3: 0.33 m³ | S3: Concrete-Rectangular Beam | T3: 450 | U3: Structural Framing | V3: BEAM <25 mm> | W3: 450 | X3: 550 | Y3: No | Z3: Other | AA3: 0 | AB3: 2.375 | AC3: 0 | AD3: 1 | AE3: RCC_BEAM | AF3: B16 | AG3: 03 PLINTH LEVEL | AH3: One or two joins disabled | AI3: Normal | AJ3: -100 | AK3: Concrete-Rectangular Beam: B(a) - 250 X 550 | AL3: 1_FLm7iHf9TvKSeqPzC2K8 | AN3: Uniform | AO3: By Type | AP3: 0.00°
A4: 3081145 | B4: 0 | C4: Left | D4: Top | E4: 3.6175 | G4: Level : 03 PLINTH LEVEL | H4: M30 | I4: 250 | J4: 4350 | K4: 3079709 | L4: 4350 | M4: 0.5981 | N4: 0 | O4: BEAM <25 mm> | P4: New Construction | Q4: B(a) - 250 X 550 | R4: 0.60 m³ | S4: Concrete-Rectangular Beam | T4: 450 | U4: Structural Framing | V4: BEAM <25 mm> | W4: 450 | X4: 550 | Y4: No | Z4: Other | AA4: 0 | AB4: 4.35 | AC4: 0 | AD4: 1 | AE4: RCC_BEAM | AF4: B2 | AG4: 03 PLINTH LEVEL | AH4: One or two joins disabled | AI4: Normal | AJ4: -100 | AK4: Concrete-Rectangular Beam: B(a) - 250 X 550 | AL4: 3ueL3jPsfCSw_2nLzW_sbG | AN4: Uniform | AO4: By Type | AP4: 0.00°
A5: 3081683 | B5: 0 | C5: Left | D5: Top | E5: 0.6175 | F5: BEAM <25 mm> | G5: Level : 03 PLINTH LEVEL | H5: M30 | I5: 250 | J5: 600 | K5: 3079709 | L5: 600 | M5: 0.0825 | N5: 0 | O5: BEAM <25 mm> | P5: New Construction | Q5: B(a) - 250 X 550 | R5: 0.08 m³ | S5: Concrete-Rectangular Beam | T5: 450 | U5: Structural Framing | V5: BEAM <25 mm> | W5: 450 | X5: 550 | Y5: No | Z5: Other | AA5: 0 | AB5: 0.6 | AC5: 0 | AD5: 1 | AE5: RCC_BEAM | AF5: B1 | AG5: 03 PLINTH LEVEL | AH5: One or two joins disabled | AI5: Normal | AJ5: -100 | AK5: Concrete-Rectangular Beam: B(a) - 250 X 550 | AL5: 2QOsO1SU19tOnmbHLze0ld | AN5: Uniform | AO5: By Type | AP5: 0.00°
A6: 3081790 | B6: 0 | C6: Left | D6: Top | E6: 3.0025 | G6: Level : 03 PLINTH LEVEL | H6: M30 | I6: 250 | J6: 3750 | K6: 3079709 | L6: 3750 | M6: 0.4414 | N6: 0 | O6: BEAM <25 mm> | P6: New Construction | Q6: B(a) - 250 X 550 | R6: 0.44 m³ | S6: Concrete-Rectangular Beam | T6: 450 | U6: Structural Framing | V6: BEAM <25 mm> | W6: 450 | X6: 550 | Y6: No | Z6: Other | AA6: 0 | AB6: 3.75 | AC6: 0 | AD6: 1 | AE6: RCC_BEAM | AF6: B13 | AG6: 03 PLINTH LEVEL | AH6: One or two joins disabled | AI6: Normal | AJ6: -100 | AK6: Concrete-Rectangular Beam: B(a) - 250 X 550 | AL6: 0JmCRR8Mv3Ue51A2BTptpQ | AN6: Uniform | AO6: By Type | AP6: 0.00°
A7: 3081898 | B7: 0 | C7: Left | D7: Top | E7: 2.735 | F7: BEAM <25 mm> | G7: Level : 03 PLINTH LEVEL | H7: M30 | I7: 200 | J7: 3500 | K7: 3089018 | L7: 3500 | M7: 0.385 | N7: 0 | O7: BEAM <25 mm> | P7: New Construction | Q7: B(a) - 200 X 550 | R7: 0.39 m³ | S7: Concrete-Rectangular Beam | T7: 450 | U7: Structural Framing | V7: BEAM <25 mm> | W7: 450 | X7: 550 | Y7: No | Z7: Other | AA7: 0 | AB7: 3.5 | AC7: 0 | AD7: 1 | AE7: RCC_BEAM | AF7: B9 | AG7: 03 PLINTH LEVEL | AH7: One or two joins disabled | AI7: Normal | AJ7: -100 | AK7: Concrete-Rectangular Beam: B(a) - 200 X 550 | AL7: 0JmCRR8Mv3Ue51A2BTptnE | AN7: Uniform | AO7: By Type | AP7: 0.00°
A8: 3082011 | B8: 0 | C8: Left | D8: Top | E8: 3.14 | G8: Level : 03 PLINTH LEVEL | H8: M30 | I8: 200 | J8: 4050 | K8: 3181454 | L8: 4050 | M8: 0.4414 | N8: 0 | O8: BEAM <25 mm> | P8: New Construction | Q8: B(b) - 200 X 550 | R8: 0.44 m³ | S8: Concrete-Rectangular Beam | T8: 450 | U8: Structural Framing | V8: BEAM <25 mm> | W8: 450 | X8: 550 | Y8: No | Z8: Other | AA8: 0 | AB8: 4.05 | AC8: 0 | AD8: 1 | AE8: RCC_BEAM | AF8: B4 | AG8: 03 PLINTH LEVEL | AH8: One or two joins disabled | AI8: Normal | AJ8: -100 | AK8: Concrete-Rectangular Beam: B(b) - 200 X 550 | AL8: 16K_Pi6W9ECvycG_Su1SH8 | AN8: Uniform | AO8: By Type | AP8: 0.00°
A9: 3082267 | B9: 0 | C9: Left | D9: Top | E9: 1.535 | F9: BEAM <25 mm> | G9: Level : 03 PLINTH LEVEL | H9: M30 | I9: 200 | J9: 1900 | K9: 3181454 | L9: 1900 | M9: 0.209 | N9: -200 | O9: BEAM <25 mm> | P9: New Construction | Q9: B(b) - 200 X 550 | R9: 0.21 m³ | S9: Concrete-Rectangular Beam | T9: 450 | U9: Structural Framing | V9: BEAM <25 mm> | W9: 250 | X9: 550 | Y9: No | Z9: Other | AA9: 0 | AB9: 1.9 | AC9: 0 | AD9: 1 | AE9: RCC_BEAM | AF9: B11 | AG9: 03 PLINTH LEVEL | AH9: One or two joins disabled | AI9: Normal | AJ9: -300 | AK9: Concrete-Rectangular Beam: B(b) - 200 X 550 | AL9: 3qutUK42D889pvIpBUtKyU | AN9: Uniform | AO9: By Type | AP9: 0.00°
A10: 3082514 | B10: 0 | C10: Left | D10: Top | E10: 1.2575 | G10: Level : 03 PLINTH LEVEL | H10: M30 | I10: 250 | J10: 1400 | K10: 3079709 | L10: 1400 | M10: 0.1925 | N10: 0 | O10: BEAM <25 mm> | P10: New Construction | Q10: B(a) - 250 X 550 | R10: 0.19 m³ | S10: Concrete-Rectangular Beam | T10: 450 | U10: Structural Framing | V10: BEAM <25 mm> | W10: 450 | X10: 550 | Y10: No | Z10: Other | AA10: 0 | AB10: 1.4 | AC10: 0 | AD10: 1 | AE10: RCC_BEAM | AF10: B5 | AG10: 03 PLINTH LEVEL | AH10: One or two joins disabled | AI10: Normal | AJ10: -100 | AK10: Concrete-Rectangular Beam: B(a) - 250 X 550 | AL10: 1w7DuRZyT28QZO5z9zRhh8 | AN10: Uniform | AO10: By Type | AP10: 0.00°
A11: 3082627 | B11: 0 | C11: Left | D11: Top | E11: 1.6175 | G11: Level : 03 PLINTH LEVEL | H11: M30 | I11: 250 | J11: 1850 | K11: 3079709 | L11: 1850 | M11: 0.2544 | N11: 0 | O11: BEAM <25 mm> | P11: New Construction | Q11: B(a) - 250 X 550 | R11: 0.25 m³ | S11: Concrete-Rectangular Beam | T11: 450 | U11: Structural Framing | V11: BEAM <25 mm> | W11: 450 | X11: 550 | Y11: No | Z11: Other | AA11: 0 | AB11: 1.85 | AC11: 0 | AD11: 1 | AE11: RCC_BEAM | AF11: B3 | AG11: 03 PLINTH LEVEL | AH11: One or two joins disabled | AI11: Normal | AJ11: -100 | AK11: Concrete-Rectangular Beam: B(a) - 250 X 550 | AL11: 1WbrjRl9L8V9UleaBo896L | AN11: Uniform | AO11: By Type | AP11: 0.00°
A12: 3082731 | B12: 0 | C12: Left | D12: Top | E12: 4.2175 | G12: Level : 03 PLINTH LEVEL | H12: M30 | I12: 250 | J12: 5100 | K12: 3079709 | L12: 5100 | M12: 0.7013 | N12: 0 | O12: BEAM <25 mm> | P12: New Construction | Q12: B(a) - 250 X 550 | R12: 0.70 m³ | S12: Concrete-Rectangular Beam | T12: 450 | U12: Structural Framing | V12: BEAM <25 mm> | W12: 450 | X12: 550 | Y12: No | Z12: Other | AA12: 0 | AB12: 5.1 | AC12: 0 | AD12: 1 | AE12: RCC_BEAM | AF12: B15 | AG12: 03 PLINTH LEVEL | AH12: One or two joins disabled | AI12: Normal | AJ12: -100 | AK12: Concrete-Rectangular Beam: B(a) - 250 X 550 | AL12: 1WbrjRl9L8V9UleaBo897z | AN12: Uniform | AO12: By Type | AP12: 0.00°
A13: 3082921 | B13: 0 | C13: Right | D13: Top | E13: 7.475 | F13: BEAM <25 mm> | G13: Level : 03 PLINTH LEVEL | H13: M30 | I13: 300 | J13: 8600 | K13: 3083275 | L13: 8600 | M13: 1.419 | N13: 0 | O13: BEAM <25 mm> | P13: New Construction | Q13: B(a) - 300 X 550 | R13: 1.42 m³ | S13: Concrete-Rectangular Beam | T13: 450 | U13: Structural Framing | V13: BEAM <25 mm> | W13: 450 | X13: 550 | Y13: No | Z13: Other | AA13: 0 | AB13: 8.6 | AC13: 0 | AD13: 1 | AE13: RCC_BEAM | AF13: B6 | AG13: 03 PLINTH LEVEL | AH13: One or two joins disabled | AI13: Normal | AJ13: -100 | AK13: Concrete-Rectangular Beam: B(a) - 300 X 550 | AL13: 0Zmr2B1_X81OwsbsfMe5Lp | AN13: Uniform | AO13: By Type | AP13: 0.00°
A14: 3083476 | B14: 0 | C14: Right | D14: Top | E14: 4.2655 | F14: BEAM <25 mm> | G14: Level : 03 PLINTH LEVEL | H14: M30 | I14: 250 | J14: 5160 | K14: 3079709 | L14: 5160 | M14: 0.7095 | N14: 0 | O14: BEAM <25 mm> | P14: New Construction | Q14: B(a) - 250 X 550 | R14: 0.71 m³ | S14: Concrete-Rectangular Beam | T14: 450 | U14: Structural Framing | V14: BEAM <25 mm> | W14: 450 | X14: 550 | Y14: No | Z14: Other | AA14: 0 | AB14: 5.16 | AC14: 0 | AD14: 1 | AE14: RCC_BEAM | AF14: B7 | AG14: 03 PLINTH LEVEL | AH14: One or two joins disabled | AI14: Normal | AJ14: -100 | AK14: Concrete-Rectangular Beam: B(a) - 250 X 550 | AL14: 2utMYCOmrDffed6MpfxG0E | AN14: Uniform | AO14: By Type | AP14: 0.00°
A15: 3083539 | B15: 0 | C15: Left | D15: Top | E15: 3.2175 | F15: BEAM <25 mm> | G15: Level : 03 PLINTH LEVEL | H15: M30 | I15: 250 | J15: 3850 | K15: 3079709 | L15: 3850 | M15: 0.5294 | N15: 0 | O15: BEAM <25 mm> | P15: New Construction | Q15: B(a) - 250 X 550 | R15: 0.53 m³ | S15: Concrete-Rectangular Beam | T15: 450 | U15: Structural Framing | V15: BEAM <25 mm> | W15: 450 | X15: 550 | Y15: No | Z15: Other | AA15: 0 | AB15: 3.85 | AC15: 0 | AD15: 1 | AE15: RCC_BEAM | AF15: B8 | AG15: 03 PLINTH LEVEL | AH15: One or two joins disabled | AI15: Normal | AJ15: -100 | AK15: Concrete-Rectangular Beam: B(a) - 250 X 550 | AL15: 2utMYCOmrDffed6MpfxG79 | AN15: Uniform | AO15: By Type | AP15: 0.00°
A16: 3083594 | B16: 0 | C16: Left | D16: Top | E16: 3.2175 | F16: BEAM <25 mm> | G16: Level : 03 PLINTH LEVEL | H16: M30 | I16: 250 | J16: 3850 | K16: 3079709 | L16: 3850 | M16: 0.5294 | N16: 0 | O16: BEAM <25 mm> | P16: New Construction | Q16: B(a) - 250 X 550 | R16: 0.53 m³ | S16: Concrete-Rectangular Beam | T16: 450 | U16: Structural Framing | V16: BEAM <25 mm> | W16: 450 | X16: 550 | Y16: No | Z16: Other | AA16: 0 | AB16: 3.85 | AC16: 0 | AD16: 1 | AE16: RCC_BEAM | AF16: B12 | AG16: 03 PLINTH LEVEL | AH16: One or two joins disabled | AI16: Normal | AJ16: -100 | AK16: Concrete-Rectangular Beam: B(a) - 250 X 550 | AL16: 2utMYCOmrDffed6MpfxG6G | AN16: Uniform | AO16: By Type | AP16: 0.00°
A17: 3085142 | B17: 0 | C17: Left | D17: Top | E17: 1.9775 | G17: Level : 03 PLINTH LEVEL | H17: M30 | I17: 250 | J17: 2300 | K17: 3079709 | L17: 2300 | M17: 0.3163 | N17: 0 | O17: BEAM <25 mm> | P17: New Construction | Q17: B(a) - 250 X 550 | R17: 0.32 m³ | S17: Concrete-Rectangular Beam | T17: 450 | U17: Structural Framing | V17: BEAM <25 mm> | W17: 450 | X17: 550 | Y17: No | Z17: Other | AA17: 0 | AB17: 2.3 | AC17: 0 | AD17: 1 | AE17: RCC_BEAM | AF17: B17 | AG17: 03 PLINTH LEVEL | AH17: One or two joins disabled | AI17: Normal | AJ17: -100 | AK17: Concrete-Rectangular Beam: B(a) - 250 X 550 | AL17: 0BBj8nW1D6ae_3yS5pWgAv | AN17: Uniform | AO17: By Type | AP17: 0.00°
A18: 3108891 | B18: 0 | C18: Left | D18: Top | E18: 0.56 | F18: BEAM <25 mm> | G18: Level : 04 1ST LEVEL | H18: M30 | I18: 200 | J18: 600 | K18: 3089018 | L18: 600 | M18: 0.066 | N18: 0 | O18: BEAM <25 mm> | P18: New Construction | Q18: B(a) - 200 X 550 | R18: 0.07 m³ | S18: Concrete-Rectangular Beam | T18: 6000 | U18: Structural Framing | V18: BEAM <25 mm> | W18: 6000 | X18: 550 | Y18: No | Z18: Other | AA18: 0 | AB18: 0.6 | AC18: 0 | AD18: 1 | AE18: RCC_BEAM | AF18: B44 | AG18: 04 1ST LEVEL | AH18: One or two joins disabled | AI18: Normal | AJ18: 5450 | AK18: Concrete-Rectangular Beam: B(a) - 200 X 550 | AL18: 1Yaf6MhzfD4f6xf1L8Ohw$ | AN18: Uniform | AO18: By Type | AP18: 0.00°
A19: 3108893 | B19: 0 | C19: Right | D19: Top | E19: 1.9475 | F19: BEAM <25 mm> | G19: Level : 04 1ST LEVEL | H19: M30 | I19: 200 | J19: 2450 | K19: 3089018 | L19: 2450 | M19: 0.2695 | N19: 0 | O19: BEAM <25 mm> | P19: New Construction | Q19: B(a) - 200 X 550 | R19: 0.27 m³ | S19: Concrete-Rectangular Beam | T19: 6000 | U19: Structural Framing | V19: BEAM <25 mm> | W19: 6000 | X19: 550 | Y19: No | Z19: Other | AA19: 0 | AB19: 2.45 | AC19: 0 | AD19: 1 | AE19: RCC_BEAM | AF19: B1 | AG19: 04 1ST LEVEL | AH19: One or two joins disabled | AI19: Normal | AJ19: 5450 | AK19: Concrete-Rectangular Beam: B(a) - 200 X 550 | AL19: 1Yaf6MhzfD4f6xf1L8Ohwv | AN19: Uniform | AO19: By Type | AP19: 0.00°
A20: 3108895 | B20: 0 | C20: Right | D20: Top | E20: 0.56 | F20: BEAM <25 mm> | G20: Level : 04 1ST LEVEL | H20: M30 | I20: 200 | J20: 600 | K20: 3089018 | L20: 600 | M20: 0.066 | N20: 0 | O20: BEAM <25 mm> | P20: New Construction | Q20: B(a) - 200 X 550 | R20: 0.07 m³ | S20: Concrete-Rectangular Beam | T20: 6000 | U20: Structural Framing | V20: BEAM <25 mm> | W20: 6000 | X20: 550 | Y20: No | Z20: Other | AA20: 0 | AB20: 0.6 | AC20: 0 | AD20: 1 | AE20: RCC_BEAM | AF20: B37 | AG20: 04 1ST LEVEL | AH20: One or two joins disabled | AI20: Normal | AJ20: 5450 | AK20: Concrete-Rectangular Beam: B(a) - 200 X 550 | AL20: 1Yaf6MhzfD4f6xf1L8Ohwx | AN20: Uniform | AO20: By Type | AP20: 0.00°
A21: 3108897 | B21: 0 | C21: Right | D21: Top | E21: 0.2925 | F21: BEAM <25 mm> | G21: Level : 04 1ST LEVEL | H21: M30 | I21: 300 | J21: 150 | K21: 3089020 | L21: 150 | M21: 0.0247 | N21: 0 | O21: BEAM <25 mm> | P21: New Construction | Q21: B(b) - 300 X 550 | R21: 0.02 m³ | S21: Concrete-Rectangular Beam | T21: 6000 | U21: Structural Framing | V21: BEAM <25 mm> | W21: 6000 | X21: 550 | Y21: No | Z21: Other | AA21: 0 | AB21: 0.15 | AC21: 0 | AD21: 1 | AE21: RCC_BEAM | AF21: B2A | AG21: 04 1ST LEVEL | AH21: One or two joins disabled | AI21: Normal | AJ21: 5450 | AK21: Concrete-Rectangular Beam: B(b) - 300 X 550 | AL21: 1Yaf6MhzfD4f6xf1L8Ohw5 | AN21: Uniform | AO21: By Type | AP21: 0.00°
A22: 3108899 | B22: 0 | C22: Left | D22: Top | E22: 0.2925 | F22: BEAM <25 mm> | G22: Level : 04 1ST LEVEL | H22: M30 | I22: 300 | J22: 150 | K22: 3089020 | L22: 150 | M22: 0.0248 | N22: 0 | O22: BEAM <25 mm> | P22: New Construction | Q22: B(b) - 300 X 550 | R22: 0.02 m³ | S22: Concrete-Rectangular Beam | T22: 6000 | U22: Structural Framing | V22: BEAM <25 mm> | W22: 6000 | X22: 550 | Y22: No | Z22: Other | AA22: 0 | AB22: 0.15 | AC22: 0 | AD22: 1 | AE22: RCC_BEAM | AF22: B2A | AG22: 04 1ST LEVEL | AH22: One or two joins disabled | AI22: Normal | AJ22: 5450 | AK22: Concrete-Rectangular Beam: B(b) - 300 X 550 | AL22: 1Yaf6MhzfD4f6xf1L8Ohw7 | AN22: Uniform | AO22: By Type | AP22: 0.00°
A23: 3108901 | B23: 0 | C23: Right | D23: Top | E23: 2.885 | F23: BEAM <25 mm> | G23: Level : 04 1ST LEVEL | H23: M30 | I23: 200 | J23: 3700 | K23: 3089018 | L23: 3700 | M23: 0.407 | N23: 0 | O23: BEAM <25 mm> | P23: New Construction | Q23: B(a) - 200 X 550 | R23: 0.41 m³ | S23: Concrete-Rectangular Beam | T23: 6000 | U23: Structural Framing | V23: BEAM <25 mm> | W23: 6000 | X23: 550 | Y23: No | Z23: Other | AA23: 0 | AB23: 3.7 | AC23: 0 | AD23: 1 | AE23: RCC_BEAM | AF23: B32 | AG23: 04 1ST LEVEL | AH23: One or two joins disabled | AI23: Normal | AJ23: 5450 | AK23: Concrete-Rectangular Beam: B(a) - 200 X 550 | AL23: 1Yaf6MhzfD4f6xf1L8Ohw1 | AN23: Uniform | AO23: By Type | AP23: 0.00°
A24: 3108903 | B24: 0 | C24: Right | D24: Top | E24: 0.785 | F24: BEAM <25 mm> | G24: Level : 04 1ST LEVEL | H24: M30 | I24: 200 | J24: 900 | K24: 3089018 | L24: 900 | M24: 0.099 | N24: 0 | O24: BEAM <25 mm> | P24: New Construction | Q24: B(a) - 200 X 550 | R24: 0.10 m³ | S24: Concrete-Rectangular Beam | T24: 6000 | U24: Structural Framing | V24: BEAM <25 mm> | W24: 6000 | X24: 550 | Y24: No | Z24: Other | AA24: 0 | AB24: 0.9 | AC24: 0 | AD24: 1 | AE24: RCC_BEAM | AF24: B6 | AG24: 04 1ST LEVEL | AH24: One or two joins disabled | AI24: Normal | AJ24: 5450 | AK24: Concrete-Rectangular Beam: B(a) - 200 X 550 | AL24: 1Yaf6MhzfD4f6xf1L8Ohw3 | AN24: Uniform | AO24: By Type | AP24: 0.00°
A25: 3108905 | B25: 0 | C25: Right | D25: Top | E25: 0.6325 | F25: BEAM <25 mm> | G25: Level : 04 1ST LEVEL | H25: M30 | I25: 300 | J25: 550 | K25: 3089020 | L25: 550 | M25: 0.0908 | N25: 0 | O25: BEAM <25 mm> | P25: New Construction | Q25: B(b) - 300 X 550 | R25: 0.09 m³ | S25: Concrete-Rectangular Beam | T25: 6000 | U25: Structural Framing | V25: BEAM <25 mm> | W25: 6000 | X25: 550 | Y25: No | Z25: Other | AA25: 0 | AB25: 0.55 | AC25: 0 | AD25: 1 | AE25: RCC_BEAM | AF25: B3 | AG25: 04 1ST LEVEL | AH25: One or two joins disabled | AI25: Normal | AJ25: 5450 | AK25: Concrete-Rectangular Beam: B(b) - 300 X 550 | AL25: 1Yaf6MhzfD4f6xf1L8OhwD | AN25: Uniform | AO25: By Type | AP25: 0.00°
A26: 3108907 | B26: 0 | C26: Left | D26: Top | E26: 7.39 | F26: BEAM <25 mm> | G26: Level : 04 1ST LEVEL | H26: M30 | I26: 300 | J26: 8500 | K26: 3089020 | L26: 8500 | M26: 1.4025 | N26: 0 | O26: BEAM <25 mm> | P26: New Construction | Q26: B(b) - 300 X 550 | R26: 1.40 m³ | S26: Concrete-Rectangular Beam | T26: 6000 | U26: Structural Framing | V26: BEAM <25 mm> | W26: 6000 | X26: 550 | Y26: No | Z26: Other | AA26: 0 | AB26: 8.5 | AC26: 0 | AD26: 1 | AE26: RCC_BEAM | AF26: B2 | AG26: 04 1ST LEVEL | AH26: One or two joins disabled | AI26: Normal | AJ26: 5450 | AK26: Concrete-Rectangular Beam: B(b) - 300 X 550 | AL26: 1Yaf6MhzfD4f6xf1L8OhwF | AN26: Uniform | AO26: By Type | AP26: 0.00°
A27: 3108909 | B27: 0 | C27: Left | D27: Top | E27: 3.4475 | F27: BEAM <25 mm> | G27: Level : 04 1ST LEVEL | H27: M30 | I27: 200 | J27: 4450 | K27: 3089018 | L27: 4450 | M27: 0.4895 | N27: 0 | O27: BEAM <25 mm> | P27: New Construction | Q27: B(a) - 200 X 550 | R27: 0.49 m³ | S27: Concrete-Rectangular Beam | T27: 6000 | U27: Structural Framing | V27: BEAM <25 mm> | W27: 6000 | X27: 550 | Y27: No | Z27: Other | AA27: 0 | AB27: 4.45 | AC27: 0 | AD27: 1 | AE27: RCC_BEAM | AF27: B52 | AG27: 04 1ST LEVEL | AH27: One or two joins disabled | AI27: Normal | AJ27: 5450 | AK27: Concrete-Rectangular Beam: B(a) - 200 X 550 | AL27: 1Yaf6MhzfD4f6xf1L8Ohw9 | AN27: Uniform | AO27: By Type | AP27: 0.00°
A28: 3108911 | B28: 0 | C28: Left | D28: Top | E28: 0.785 | F28: BEAM <25 mm> | G28: Level : 04 1ST LEVEL | H28: M30 | I28: 200 | J28: 900 | K28: 3089018 | L28: 900 | M28: 0.099 | N28: 0 | O28: BEAM <25 mm> | P28: New Construction | Q28: B(a) - 200 X 550 | R28: 0.10 m³ | S28: Concrete-Rectangular Beam | T28: 6000 | U28: Structural Framing | V28: BEAM <25 mm> | W28: 6000 | X28: 550 | Y28: No | Z28: Other | AA28: 0 | AB28: 0.9 | AC28: 0 | AD28: 1 | AE28: RCC_BEAM | AF28: B9 | AG28: 04 1ST LEVEL | AH28: One or two joins disabled | AI28: Normal | AJ28: 5450 | AK28: Concrete-Rectangular Beam: B(a) - 200 X 550 | AL28: 1Yaf6MhzfD4f6xf1L8OhwB | AN28: Uniform | AO28: By Type | AP28: 0.00°
A29: 3108913 | B29: 0 | C29: Right | D29: Top | E29: 2.36 | F29: BEAM <25 mm> | G29: Level : 04 1ST LEVEL | H29: M30 | I29: 200 | J29: 3000 | K29: 3089018 | L29: 3000 | M29: 0.33 | N29: 0 | O29: BEAM <25 mm> | P29: New Construction | Q29: B(a) - 200 X 550 | R29: 0.33 m³ | S29: Concrete-Rectangular Beam | T29: 6000 | U29: Structural Framing | V29: BEAM <25 mm> | W29: 6000 | X29: 550 | Y29: No | Z29: Other | AA29: 0 | AB29: 3 | AC29: 0 | AD29: 1 | AE29: RCC_BEAM | AF29: B36 | AG29: 04 1ST LEVEL | AH29: One or two joins disabled | AI29: Normal | AJ29: 5450 | AK29: Concrete-Rectangular Beam: B(a) - 200 X 550 | AL29: 1Yaf6MhzfD4f6xf1L8OhwL | AN29: Uniform | AO29: By Type | AP29: 0.00°
... A33: 3108921 | B33: 0 | C33: Right | D33: Top | E33: 0.7025 | F33: BEAM <25 mm> | G33: Level : 04 1ST LEVEL | H33: M30 | I33: 200 | J33: 1150 | K33: 3089028 | L33: 1150 | M33: 0.0805 | N33: -200 | O33: BEAM <25 mm> | P33: New Construction | Q33: B(f) - 200 X 350 | R33: 0.08 m³ | S33: Concrete-Rectangular Beam | T33: 6000 | U33: Structural Framing | V33: BEAM <25 mm> | W33: 5800 | X33: 350 | Y33: No | Z33: Other | AA33: 0 | AB33: 1.15 | AC33: 0 | AD33: 1 | AE33: RCC_BEAM | AF33: B4 | AG33: 04 1ST LEVEL | AH33: One or two joins disabled | AI33: Normal | AJ33: 5450 | AK33: Concrete-Rectangular Beam: B(f) - 200 X 350 | AL33: 1Yaf6MhzfD4f6xf1L8OhwT | AN33: Uniform | AO33: By Type | AP33: 0.00°
A34: 3108923 | B34: 0 | C34: Right | D34: Top | E34: 3.4475 | G34: Level : 04 1ST LEVEL | H34: M30 | I34: 200 | J34: 4450 | K34: 3089018 | L34: 4450 | M34: 0.4895 | N34: 0 | O34: BEAM <25 mm> | P34: New Construction | Q34: B(a) - 200 X 550 | R34: 0.49 m³ | S34: Concrete-Rectangular Beam | T34: 6000 | U34: Structural Framing | V34: BEAM <25 mm> | W34: 6000 | X34: 550 | Y34: No | Z34: Other | AA34: 0 | AB34: 4.45 | AC34: 0 | AD34: 1 | AE34: RCC_BEAM | AF34: B42 | AG34: 04 1ST LEVEL | AH34: One or two joins disabled | AI34: Normal | AJ34: 5450 | AK34: Concrete-Rectangular Beam: B(a) - 200 X 550 | AL34: 1Yaf6MhzfD4f6xf1L8OhwV | AN34: Uniform | AO34: By Type | AP34: 0.00°
A35: 3108925 | B35: 0 | C35: Left | D35: Top | E35: 6.965 | F35: BEAM <25 mm> | G35: Level : 04 1ST LEVEL | H35: M30 | I35: 300 | J35: 8000 | K35: 3089020 | L35: 8000 | M35: 1.32 | N35: 0 | O35: BEAM <25 mm> | P35: New Construction | Q35: B(b) - 300 X 550 | R35: 1.32 m³ | S35: Concrete-Rectangular Beam | T35: 6000 | U35: Structural Framing | V35: BEAM <25 mm> | W35: 6000 | X35: 550 | Y35: No | Z35: Other | AA35: 0 | AB35: 8 | AC35: 0 | AD35: 1 | AE35: RCC_BEAM | AF35: B11 | AG35: 04 1ST LEVEL | AH35: One or two joins disabled | AI35: Normal | AJ35: 5450 | AK35: Concrete-Rectangular Beam: B(b) - 300 X 550 | AL35: 1Yaf6MhzfD4f6xf1L8OhwP | AN35: Uniform | AO35: By Type | AP35: 0.00°
A36: 3108927 | B36: 0 | C36: Right | D36: Top | E36: 1.0475 | F36: BEAM <25 mm> | G36: Level : 04 1ST LEVEL | H36: M30 | I36: 200 | J36: 1250 | K36: 3089018 | L36: 1250 | M36: 0.1375 | N36: 0 | O36: BEAM <25 mm> | P36: New Construction | Q36: B(a) - 200 X 550 | R36: 0.14 m³ | S36: Concrete-Rectangular Beam | T36: 6000 | U36: Structural Framing | V36: BEAM <25 mm> | W36: 6000 | X36: 550 | Y36: No | Z36: Other | AA36: 0 | AB36: 1.25 | AC36: 0 | AD36: 1 | AE36: RCC_BEAM | AF36: B28 | AG36: 04 1ST LEVEL | AH36: One or two joins disabled | AI36: Normal | AJ36: 5450 | AK36: Concrete-Rectangular Beam: B(a) - 200 X 550 | AL36: 1Yaf6MhzfD4f6xf1L8OhwR | AN36: Uniform | AO36: By Type | AP36: 0.00°
A37: 3108929 | B37: 0 | C37: Left | D37: Top | E37: 0.785 | F37: BEAM <25 mm> | G37: Level : 04 1ST LEVEL | H37: M30 | I37: 200 | J37: 900 | K37: 3089018 | L37: 900 | M37: 0.099 | N37: 0 | O37: BEAM <25 mm> | P37: New Construction | Q37: B(a) - 200 X 550 | R37: 0.10 m³ | S37: Concrete-Rectangular Beam | T37: 6000 | U37: Structural Framing | V37: BEAM <25 mm> | W37: 6000 | X37: 550 | Y37: No | Z37: Other | AA37: 0 | AB37: 0.9 | AC37: 0 | AD37: 1 | AE37: RCC_BEAM | AF37: B10 | AG37: 04 1ST LEVEL | AH37: One or two joins disabled | AI37: Normal | AJ37: 5450 | AK37: Concrete-Rectangular Beam: B(a) - 200 X 550 | AL37: 1Yaf6MhzfD4f6xf1L8Ohxb | AN37: Uniform | AO37: By Type | AP37: 0.00°
A38: 3108931 | B38: 0 | C38: Left | D38: Top | E38: 1.1085 | F38: BEAM <25 mm> | G38: Level : 04 1ST LEVEL | H38: M30 | I38: 300 | J38: 1110 | K38: 3089020 | L38: 1110 | M38: 0.1832 | N38: 0 | O38: BEAM <25 mm> | P38: New Construction | Q38: B(b) - 300 X 550 | R38: 0.18 m³ | S38: Concrete-Rectangular Beam | T38: 6000 | U38: Structural Framing | V38: BEAM <25 mm> | W38: 6000 | X38: 550 | Y38: No | Z38: Other | AA38: 0 | AB38: 1.11 | AC38: 0 | AD38: 1 | AE38: RCC_BEAM | AF38: B12 | AG38: 04 1ST LEVEL | AH38: One or two joins disabled | AI38: Normal | AJ38: 5450 | AK38: Concrete-Rectangular Beam: B(b) - 300 X 550 | AL38: 1Yaf6MhzfD4f6xf1L8Ohxd | AN38: Uniform | AO38: By Type | AP38: 0.00°
A39: 3108933 | B39: 0 | C39: Left | D39: Top | E39: 1.0475 | F39: BEAM <25 mm> | G39: Level : 04 1ST LEVEL | H39: M30 | I39: 200 | J39: 1250 | K39: 3089018 | L39: 1250 | M39: 0.1375 | N39: 0 | O39: BEAM <25 mm> | P39: New Construction | Q39: B(a) - 200 X 550 | R39: 0.14 m³ | S39: Concrete-Rectangular Beam | T39: 6000 | U39: Structural Framing | V39: BEAM <25 mm> | W39: 6000 | X39: 550 | Y39: No | Z39: Other | AA39: 0 | AB39: 1.25 | AC39: 0 | AD39: 1 | AE39: RCC_BEAM | AF39: B55 | AG39: 04 1ST LEVEL | AH39: One or two joins disabled | AI39: Normal | AJ39: 5450 | AK39: Concrete-Rectangular Beam: B(a) - 200 X 550 | AL39: 1Yaf6MhzfD4f6xf1L8OhxX | AN39: Uniform | AO39: By Type | AP39: 0.00°
A40: 3108935 | B40: 0 | C40: Right | D40: Top | E40: 2.285 | F40: BEAM <25 mm> | G40: Level : 04 1ST LEVEL | H40: M30 | I40: 200 | J40: 2900 | K40: 3089018 | L40: 2900 | M40: 0.319 | N40: 0 | O40: BEAM <25 mm> | P40: New Construction | Q40: B(a) - 200 X 550 | R40: 0.32 m³ | S40: Concrete-Rectangular Beam | T40: 6000 | U40: Structural Framing | V40: BEAM <25 mm> | W40: 6000 | X40: 550 | Y40: No | Z40: Other | AA40: 0 | AB40: 2.9 | AC40: 0 | AD40: 1 | AE40: RCC_BEAM | AF40: B31 | AG40: 04 1ST LEVEL | AH40: One or two joins disabled | AI40: Normal | AJ40: 5450 | AK40: Concrete-Rectangular Beam: B(a) - 200 X 550 | AL40: 1Yaf6MhzfD4f6xf1L8OhxZ | AN40: Uniform | AO40: By Type | AP40: 0.00°
A41: 3108937 | B41: 0 | C41: Left | D41: Top | E41: 4.2575 | F41: BEAM <25 mm> | G41: Level : 04 1ST LEVEL | H41: M30 | I41: 250 | J41: 5150 | K41: 3089024 | L41: 5150 | M41: 0.7081 | N41: 0 | O41: BEAM <25 mm> | P41: New Construction | Q41: B(d) - 250 X 550 | R41: 0.71 m³ | S41: Concrete-Rectangular Beam | T41: 6000 | U41: Structural Framing | V41: BEAM <25 mm> | W41: 6000 | X41: 550 | Y41: No | Z41: Other | AA41: 0 | AB41: 5.15 | AC41: 0 | AD41: 1 | AE41: RCC_BEAM | AF41: B54 | AG41: 04 1ST LEVEL | AH41: One or two joins disabled | AI41: Normal | AJ41: 5450 | AK41: Concrete-Rectangular Beam: B(d) - 250 X 550 | AL41: 1Yaf6MhzfD4f6xf1L8Ohxj | AN41: Uniform | AO41: By Type | AP41: 0.00°
A42: 3108939 | B42: 0 | C42: Left | D42: Top | E42: 0.6175 | F42: BEAM <25 mm> | G42: Level : 04 1ST LEVEL | H42: M30 | I42: 250 | J42: 600 | K42: 3089024 | L42: 600 | M42: 0.0825 | N42: 0 | O42: BEAM <25 mm> | P42: New Construction | Q42: B(d) - 250 X 550 | R42: 0.08 m³ | S42: Concrete-Rectangular Beam | T42: 6000 | U42: Structural Framing | V42: BEAM <25 mm> | W42: 6000 | X42: 550 | Y42: No | Z42: Other | AA42: 0 | AB42: 0.6 | AC42: 0 | AD42: 1 | AE42: RCC_BEAM | AF42: B13 | AG42: 04 1ST LEVEL | AH42: One or two joins disabled | AI42: Normal | AJ42: 5450 | AK42: Concrete-Rectangular Beam: B(d) - 250 X 550 | AL42: 1Yaf6MhzfD4f6xf1L8Ohxl | AN42: Uniform | AO42: By Type | AP42: 0.00°
A43: 3108941 | B43: 0 | C43: Left | D43: Top | E43: 4.9455 | F43: BEAM <25 mm> | G43: Level : 04 1ST LEVEL | H43: M30 | I43: 250 | J43: 6010 | K43: 3089024 | L43: 6010 | M43: 0.8264 | N43: 0 | O43: BEAM <25 mm> | P43: New Construction | Q43: B(d) - 250 X 550 | R43: 0.83 m³ | S43: Concrete-Rectangular Beam | T43: 6000 | U43: Structural Framing | V43: BEAM <25 mm> | W43: 6000 | X43: 550 | Y43: No | Z43: Other | AA43: 0 | AB43: 6.01 | AC43: 0 | AD43: 1 | AE43: RCC_BEAM | AF43: B14 | AG43: 04 1ST LEVEL | AH43: One or two joins disabled | AI43: Normal | AJ43: 5450 | AK43: Concrete-Rectangular Beam: B(d) - 250 X 550 | AL43: 1Yaf6MhzfD4f6xf1L8Ohxf | AN43: Uniform | AO43: By Type | AP43: 0.00°
...

Sheet Column
A1: Element ID | B1: Qty: Area (m2) | C1: Rebar Cover - Other Faces | D1: GRADE OF CONCRETE | E1: Top Offset | F1: Moves With Grids | G1: Type Id | H1: Length | I1: Qty: Volume (m3) | J1: Base Level | K1: Base Offset | L1: Column Style | M1: Rebar Cover - Bottom Face | N1: Phase Created | O1: Type | P1: Room Bounding | Q1: Volume | R1: Family | S1: Category | T1: Rebar Cover - Top Face | U1: Has Association | V1: Qty: Length (m) | W1: Qty: Count | X1: Structural Material | Y1: ID_UNMT | Z1: Top Level | AA1: Family and Type | AB1: IfcGUID | AC1: Export to IFC | AD1: Level
A2: 3072170 | B2: 3.63 | C2: COLUMN <40 mm> | D2: M40 | E2: 0 | F2: Yes | G2: 2270699 | H2: 2800 | I2: 0.756 | J2: 01 FOUNDATION LEVEL | K2: 0 | L2: Vertical | M2: COLUMN <40 mm> | N2: New Construction | O2: C1 - 300 X 900 | P2: Yes | Q2: 0.76 m³ | R2: Concrete-Rectangular-Column | S2: Structural Columns | T2: COLUMN <40 mm> | U2: No | V2: 2.8 | W2: 1 | X2: RCC_COLUMN | Y2: P31 | Z2: 03 PLINTH LEVEL | AA2: Concrete-Rectangular-Column: C1 - 300 X 900 | AB2: 1cOR_VX$r0AOI0dQYfFQzi | AC2: By Type | AD2: 01 FOUNDATION LEVEL
A3: 3072220 | B3: 3.32 | C3: COLUMN <40 mm> | D3: M40 | E3: 0 | F3: Yes | G3: 3113818 | H3: 2800 | I3: 0.672 | J3: 01 FOUNDATION LEVEL | K3: 0 | L3: Vertical | M3: COLUMN <40 mm> | N3: New Construction | O3: C2 - 300 X 800 | P3: Yes | Q3: 0.67 m³ | R3: Concrete-Rectangular-Column | S3: Structural Columns | T3: COLUMN <40 mm> | U3: No | V3: 2.8 | W3: 1 | X3: RCC_COLUMN | Z3: 03 PLINTH LEVEL | AA3: Concrete-Rectangular-Column: C2 - 300 X 800 | AB3: 3g$5deWJz9Pw1ItRzeIhWG | AC3: By Type | AD3: 01 FOUNDATION LEVEL
A4: 3072869 | B4: 4.04 | C4: COLUMN <40 mm> | D4: M40 | E4: 0 | F4: Yes | G4: 3072865 | H4: 2800 | I4: 1.12 | J4: 01 FOUNDATION LEVEL | K4: 0 | L4: Vertical | N4: New Construction | O4: C3 - 500 X 800 | P4: Yes | Q4: 1.12 m³ | R4: Concrete-Rectangular-Column | S4: Structural Columns | T4: COLUMN <40 mm> | U4: No | V4: 2.8 | W4: 1 | X4: RCC_COLUMN | Z4: 03 PLINTH LEVEL | AA4: Concrete-Rectangular-Column: C3 - 500 X 800 | AB4: 2ohiwoKjf239MUfP$H_zLU | AC4: By Type | AD4: 01 FOUNDATION LEVEL
A5: 3072935 | B5: 4.0225 | C5: COLUMN <40 mm> | D5: M40 | E5: 0 | F5: Yes | G5: 3080622 | H5: 2800 | I5: 1.071 | J5: 01 FOUNDATION LEVEL | K5: 0 | L5: Vertical | M5: COLUMN <40 mm> | N5: New Construction | O5: SW1- 450 X 850 | P5: Yes | Q5: 1.07 m³ | R5: Concrete-Rectangular-Column | S5: Structural Columns | T5: COLUMN <40 mm> | U5: No | V5: 2.8 | W5: 1 | X5: RCC_COLUMN | Z5: 03 PLINTH LEVEL | AA5: Concrete-Rectangular-Column: SW1- 450 X 850 | AB5: 279mmlFkP8VQg8p_cJohR9 | AC5: By Type | AD5: 01 FOUNDATION LEVEL
A6: 3073001 | B6: 6.6475 | C6: COLUMN <40 mm> | D6: M40 | E6: 0 | F6: Yes | G6: 3072997 | H6: 2800 | I6: 1.365 | J6: 01 FOUNDATION LEVEL | K6: 0 | L6: Vertical | M6: COLUMN <40 mm> | N6: New Construction | O6: SW3 - 250 X 1950 | P6: Yes | Q6: 1.37 m³ | R6: Concrete-Rectangular-Column | S6: Structural Columns | T6: COLUMN <40 mm> | U6: No | V6: 2.8 | W6: 1 | X6: RCC_COLUMN | Z6: 03 PLINTH LEVEL | AA6: Concrete-Rectangular-Column: SW3 - 250 X 1950 | AB6: 3qVNAAsVTApum02lPcqKEt | AC6: By Type | AD6: 01 FOUNDATION LEVEL
A7: 3073025 | B7: 1.46 | C7: COLUMN <40 mm> | D7: M40 | E7: 0 | F7: Yes | G7: 3073021 | H7: 2800 | I7: 0.168 | J7: 01 FOUNDATION LEVEL | K7: 0 | L7: Vertical | M7: COLUMN <40 mm> | N7: New Construction | O7: SW3 - 200 X 300 | P7: Yes | Q7: 0.17 m³ | R7: Concrete-Rectangular-Column | S7: Structural Columns | T7: COLUMN <40 mm> | U7: No | V7: 2.8 | W7: 1 | X7: RCC_COLUMN | Z7: 03 PLINTH LEVEL | AA7: Concrete-Rectangular-Column: SW3 - 200 X 300 | AB7: 3qVNAAsVTApum02lPcqKHV | AC7: By Type | AD7: 01 FOUNDATION LEVEL
A8: 3075646 | B8: 6.6475 | C8: COLUMN <40 mm> | D8: M40 | E8: 0 | F8: Yes | G8: 3075811 | H8: 2800 | I8: 1.365 | J8: 01 FOUNDATION LEVEL | K8: 0 | L8: Vertical | M8: COLUMN <40 mm> | N8: New Construction | O8: SW3A - 250 X 1950 | P8: Yes | Q8: 1.37 m³ | R8: Concrete-Rectangular-Column | S8: Structural Columns | T8: COLUMN <40 mm> | U8: No | V8: 2.8 | W8: 1 | X8: RCC_COLUMN | Z8: 03 PLINTH LEVEL | AA8: Concrete-Rectangular-Column: SW3A - 250 X 1950 | AB8: 2Gt5m7wB13Yu3J4t117AYf | AC8: By Type | AD8: 01 FOUNDATION LEVEL
A9: 3075703 | B9: 2.7588 | C9: COLUMN <40 mm> | D9: M40 | E9: 0 | F9: Yes | G9: 3075838 | H9: 2800 | I9: 0.4725 | J9: 01 FOUNDATION LEVEL | K9: 0 | L9: Vertical | M9: COLUMN <40 mm> | N9: New Construction | O9: SW3A - 250 X 675 | P9: Yes | Q9: 0.47 m³ | R9: Concrete-Rectangular-Column | S9: Structural Columns | T9: COLUMN <40 mm> | U9: No | V9: 2.8 | W9: 1 | X9: RCC_COLUMN | Z9: 03 PLINTH LEVEL | AA9: Concrete-Rectangular-Column: SW3A - 250 X 675 | AB9: 2Gt5m7wB13Yu3J4t117AZW | AC9: By Type | AD9: 01 FOUNDATION LEVEL
A10: 3076026 | B10: 5.885 | C10: COLUMN <40 mm> | D10: M40 | E10: 0 | F10: Yes | G10: 3076022 | H10: 2800 | I10: 1.19 | J10: 01 FOUNDATION LEVEL | K10: 0 | L10: Vertical | M10: COLUMN <40 mm> | N10: New Construction | O10: SW4 - 250 X 1700 | P10: Yes | Q10: 1.19 m³ | R10: Concrete-Rectangular-Column | S10: Structural Columns | T10: COLUMN <40 mm> | U10: No | V10: 2.8 | W10: 1 | X10: RCC_COLUMN | Z10: 03 PLINTH LEVEL | AA10: Concrete-Rectangular-Column: SW4 - 250 X 1700 | AB10: 1JkEnnoEj7aw8NfVQaT7HK | AC10: By Type | AD10: 01 FOUNDATION LEVEL
A11: 3076226 | B11: 3.04 | C11: COLUMN <40 mm> | D11: M40 | E11: 0 | F11: Yes | G11: 3076222 | H11: 2800 | I11: 0.672 | J11: 01 FOUNDATION LEVEL | K11: 0 | L11: Vertical | M11: COLUMN <40 mm> | N11: New Construction | O11: SW6 - 400 X 600 | P11: Yes | Q11: 0.67 m³ | R11: Concrete-Rectangular-Column | S11: Structural Columns | T11: COLUMN <40 mm> | U11: No | V11: 2.8 | W11: 1 | X11: RCC_COLUMN | Z11: 03 PLINTH LEVEL | AA11: Concrete-Rectangular-Column: SW6 - 400 X 600 | AB11: 2ovWY3igbER80XEiIP5Z1M | AC11: By Type | AD11: 01 FOUNDATION LEVEL
A12: 3076643 | B12: 10.72 | C12: COLUMN <40 mm> | D12: M40 | E12: 0 | F12: Yes | G12: 3076639 | H12: 2800 | I12: 3.36 | J12: 01 FOUNDATION LEVEL | K12: 0 | L12: Vertical | M12: COLUMN <40 mm> | N12: New Construction | O12: SW7 - 400 X 3000 | P12: Yes | Q12: 3.36 m³ | R12: Concrete-Rectangular-Column | S12: Structural Columns | T12: COLUMN <40 mm> | U12: No | V12: 2.8 | W12: 1 | X12: RCC_COLUMN | Z12: 03 PLINTH LEVEL | AA12: Concrete-Rectangular-Column: SW7 - 400 X 3000 | AB12: 3AGwxIsxDFSPW7X3sFtVlp | AC12: By Type | AD12: 01 FOUNDATION LEVEL
A13: 3076721 | B13: 3.94 | C13: COLUMN <40 mm> | D13: M40 | E13: 0 | F13: Yes | G13: 3076717 | H13: 2800 | I13: 0.84 | J13: 01 FOUNDATION LEVEL | K13: 0 | L13: Vertical | M13: COLUMN <40 mm> | N13: New Construction | O13: C6 - 300 X 1000 | P13: Yes | Q13: 0.84 m³ | R13: Concrete-Rectangular-Column | S13: Structural Columns | T13: COLUMN <40 mm> | U13: No | V13: 2.8 | W13: 1 | X13: RCC_COLUMN | Z13: 03 PLINTH LEVEL | AA13: Concrete-Rectangular-Column: C6 - 300 X 1000 | AB13: 1E5fPVYML1B9eG4TrHYjpN | AC13: By Type | AD13: 01 FOUNDATION LEVEL
A14: 3076756 | B14: 4 | C14: COLUMN <40 mm> | D14: M40 | E14: 0 | F14: Yes | G14: 3076752 | H14: 2800 | I14: 1.008 | J14: 01 FOUNDATION LEVEL | K14: 0 | L14: Vertical | M14: COLUMN <40 mm> | N14: New Construction | O14: C5 - 400 X 900 | P14: Yes | Q14: 1.01 m³ | R14: Concrete-Rectangular-Column | S14: Structural Columns | T14: COLUMN <40 mm> | U14: No | V14: 2.8 | W14: 1 | X14: RCC_COLUMN | Z14: 03 PLINTH LEVEL | AA14: Concrete-Rectangular-Column: C5 - 400 X 900 | AB14: 1E5fPVYML1B9eG4TrHYjmo | AC14: By Type | AD14: 01 FOUNDATION LEVEL
A15: 3076782 | B15: 4 | C15: COLUMN <40 mm> | D15: M40 | E15: 0 | F15: Yes | G15: 3076778 | H15: 2800 | I15: 1.008 | J15: 01 FOUNDATION LEVEL | K15: 0 | L15: Vertical | M15: COLUMN <40 mm> | N15: New Construction | O15: C4 - 400 X 900 | P15: Yes | Q15: 1.01 m³ | R15: Concrete-Rectangular-Column | S15: Structural Columns | T15: COLUMN <40 mm> | U15: No | V15: 2.8 | W15: 1 | X15: RCC_COLUMN | Z15: 03 PLINTH LEVEL | AA15: Concrete-Rectangular-Column: C4 - 400 X 900 | AB15: 1E5fPVYML1B9eG4TrHYjm8 | AC15: By Type | AD15: 01 FOUNDATION LEVEL
A16: 3076920 | B16: 6.9525 | C16: COLUMN <40 mm> | D16: M40 | E16: 0 | F16: Yes | G16: 3076916 | H16: 2800 | I16: 1.435 | J16: 01 FOUNDATION LEVEL | K16: 0 | L16: Vertical | M16: COLUMN <40 mm> | N16: New Construction | O16: LW1 - 250 X 2050 | P16: Yes | Q16: 1.44 m³ | R16: Concrete-Rectangular-Column | S16: Structural Columns | T16: COLUMN <40 mm> | U16: No | V16: 2.8 | W16: 1 | X16: RCC_COLUMN | Z16: 03 PLINTH LEVEL | AA16: Concrete-Rectangular-Column: LW1 - 250 X 2050 | AB16: 0HkMLA0MP5wgflFwXOfFA9 | AC16: By Type | AD16: 01 FOUNDATION LEVEL
... A18: 3077251 | B18: 13.91 | C18: COLUMN <40 mm> | D18: M40 | E18: 0 | F18: Yes | G18: 3077247 | H18: 2800 | I18: 2.492 | J18: 01 FOUNDATION LEVEL | K18: 0 | L18: Vertical | M18: COLUMN <40 mm> | N18: New Construction | O18: LW2 - 200 X 4450 | P18: Yes | Q18: 2.49 m³ | R18: Concrete-Rectangular-Column | S18: Structural Columns | T18: COLUMN <40 mm> | U18: No | V18: 2.8 | W18: 1 | X18: RCC_COLUMN | Z18: 03 PLINTH LEVEL | AA18: Concrete-Rectangular-Column: LW2 - 200 X 4450 | AB18: 3HF6TA$qL7KxUmTx2qwlF9 | AC18: By Type | AD18: 01 FOUNDATION LEVEL
A19: 3084306 | B19: 6.93 | C19: COLUMN <40 mm> | D19: M40 | E19: 0 | F19: Yes | G19: 2270699 | H19: 5550 | I19: 1.4985 | J19: 03 PLINTH LEVEL | K19: 0 | L19: Vertical | M19: COLUMN <40 mm> | N19: New Construction | O19: C1 - 300 X 900 | P19: Yes | Q19: 1.50 m³ | R19: Concrete-Rectangular-Column | S19: Structural Columns | T19: COLUMN <40 mm> | U19: No | V19: 5.55 | W19: 1 | X19: RCC_COLUMN | Y19: P31 | Z19: 04 1ST LEVEL | AA19: Concrete-Rectangular-Column: C1 - 300 X 900 | AB19: 2JGI2Z2THB_wudpkjjxw_6 | AC19: By Type | AD19: 03 PLINTH LEVEL
A20: 3084308 | B20: 6.345 | C20: COLUMN <40 mm> | D20: M40 | E20: 0 | F20: Yes | G20: 3113818 | H20: 5550 | I20: 1.332 | J20: 03 PLINTH LEVEL | K20: 0 | L20: Vertical | M20: COLUMN <40 mm> | N20: New Construction | O20: C2 - 300 X 800 | P20: Yes | Q20: 1.33 m³ | R20: Concrete-Rectangular-Column | S20: Structural Columns | T20: COLUMN <40 mm> | U20: No | V20: 5.55 | W20: 1 | X20: RCC_COLUMN | Z20: 04 1ST LEVEL | AA20: Concrete-Rectangular-Column: C2 - 300 X 800 | AB20: 2JGI2Z2THB_wudpkjjxw_0 | AC20: By Type | AD20: 03 PLINTH LEVEL
A21: 3084310 | B21: 7.615 | C21: COLUMN <40 mm> | D21: M40 | E21: 0 | F21: Yes | G21: 3072865 | H21: 5550 | I21: 2.22 | J21: 03 PLINTH LEVEL | K21: 0 | L21: Vertical | M21: COLUMN <40 mm> | N21: New Construction | O21: C3 - 500 X 800 | P21: Yes | Q21: 2.22 m³ | R21: Concrete-Rectangular-Column | S21: Structural Columns | T21: COLUMN <40 mm> | U21: No | V21: 5.55 | W21: 1 | X21: RCC_COLUMN | Z21: 04 1ST LEVEL | AA21: Concrete-Rectangular-Column: C3 - 500 X 800 | AB21: 2JGI2Z2THB_wudpkjjxw_2 | AC21: By Type | AD21: 03 PLINTH LEVEL
A22: 3084312 | B22: 7.5975 | C22: COLUMN <40 mm> | D22: M40 | E22: 0 | F22: Yes | G22: 3080622 | H22: 5550 | I22: 2.1229 | J22: 03 PLINTH LEVEL | K22: 0 | L22: Vertical | M22: COLUMN <40 mm> | N22: New Construction | O22: SW1- 450 X 850 | P22: Yes | Q22: 2.12 m³ | R22: Concrete-Rectangular-Column | S22: Structural Columns | T22: COLUMN <40 mm> | U22: No | V22: 5.55 | W22: 1 | X22: RCC_COLUMN | Z22: 04 1ST LEVEL | AA22: Concrete-Rectangular-Column: SW1- 450 X 850 | AB22: 2JGI2Z2THB_wudpkjjxw_C | AC22: By Type | AD22: 03 PLINTH LEVEL
A23: 3084314 | B23: 12.6975 | C23: COLUMN <40 mm> | D23: M40 | E23: 0 | F23: Yes | G23: 3072997 | H23: 5550 | I23: 2.7056 | J23: 03 PLINTH LEVEL | K23: 0 | L23: Vertical | M23: COLUMN <40 mm> | N23: New Construction | O23: SW3 - 250 X 1950 | P23: Yes | Q23: 2.71 m³ | R23: Concrete-Rectangular-Column | S23: Structural Columns | T23: COLUMN <40 mm> | U23: No | V23: 5.55 | W23: 1 | X23: RCC_COLUMN | Z23: 04 1ST LEVEL | AA23: Concrete-Rectangular-Column: SW3 - 250 X 1950 | AB23: 2JGI2Z2THB_wudpkjjxw_E | AC23: By Type | AD23: 03 PLINTH LEVEL
A24: 3084316 | B24: 2.835 | C24: COLUMN <40 mm> | D24: M40 | E24: 0 | F24: Yes | G24: 3073021 | H24: 5550 | I24: 0.333 | J24: 03 PLINTH LEVEL | K24: 0 | L24: Vertical | M24: COLUMN <40 mm> | N24: New Construction | O24: SW3 - 200 X 300 | P24: Yes | Q24: 0.33 m³ | R24: Concrete-Rectangular-Column | S24: Structural Columns | T24: COLUMN <40 mm> | U24: No | V24: 5.55 | W24: 1 | X24: RCC_COLUMN | Z24: 04 1ST LEVEL | AA24: Concrete-Rectangular-Column: SW3 - 200 X 300 | AB24: 2JGI2Z2THB_wudpkjjxw_8 | AC24: By Type | AD24: 03 PLINTH LEVEL
A25: 3084318 | B25: 12.6975 | C25: COLUMN <40 mm> | D25: M40 | E25: 0 | F25: Yes | G25: 3075811 | H25: 5550 | I25: 2.7056 | J25: 03 PLINTH LEVEL | K25: 0 | L25: Vertical | M25: COLUMN <40 mm> | N25: New Construction | O25: SW3A - 250 X 1950 | P25: Yes | Q25: 2.71 m³ | R25: Concrete-Rectangular-Column | S25: Structural Columns | T25: COLUMN <40 mm> | U25: No | V25: 5.55 | W25: 1 | X25: RCC_COLUMN | Z25: 04 1ST LEVEL | AA25: Concrete-Rectangular-Column: SW3A - 250 X 1950 | AB25: 2JGI2Z2THB_wudpkjjxw_A | AC25: By Type | AD25: 03 PLINTH LEVEL
A26: 3084320 | B26: 5.3025 | C26: COLUMN <40 mm> | D26: M40 | E26: 0 | F26: Yes | G26: 3075838 | H26: 5550 | I26: 0.9366 | J26: 03 PLINTH LEVEL | K26: 0 | L26: Vertical | M26: COLUMN <40 mm> | N26: New Construction | O26: SW3A - 250 X 675 | P26: Yes | Q26: 0.94 m³ | R26: Concrete-Rectangular-Column | S26: Structural Columns | T26: COLUMN <40 mm> | U26: No | V26: 5.55 | W26: 1 | X26: RCC_COLUMN | Z26: 04 1ST LEVEL | AA26: Concrete-Rectangular-Column: SW3A - 250 X 675 | AB26: 2JGI2Z2THB_wudpkjjxw_q | AC26: By Type | AD26: 03 PLINTH LEVEL
A27: 3084324 | B27: 11.2475 | C27: COLUMN <40 mm> | D27: M40 | E27: 0 | F27: Yes | G27: 3076022 | H27: 5550 | I27: 2.3587 | J27: 03 PLINTH LEVEL | K27: 0 | L27: Vertical | M27: COLUMN <40 mm> | N27: New Construction | O27: SW4 - 250 X 1700 | P27: Yes | Q27: 2.36 m³ | R27: Concrete-Rectangular-Column | S27: Structural Columns | T27: COLUMN <40 mm> | U27: No | V27: 5.55 | W27: 1 | X27: RCC_COLUMN | Z27: 04 1ST LEVEL | AA27: Concrete-Rectangular-Column: SW4 - 250 X 1700 | AB27: 2JGI2Z2THB_wudpkjjxw_m | AC27: By Type | AD27: 03 PLINTH LEVEL
A28: 3084326 | B28: 5.79 | C28: COLUMN <40 mm> | D28: M40 | E28: 0 | F28: Yes | G28: 3076222 | H28: 5550 | I28: 1.332 | J28: 03 PLINTH LEVEL | K28: 0 | L28: Vertical | M28: COLUMN <40 mm> | N28: New Construction | O28: SW6 - 400 X 600 | P28: Yes | Q28: 1.33 m³ | R28: Concrete-Rectangular-Column | S28: Structural Columns | T28: COLUMN <40 mm> | U28: No | V28: 5.55 | W28: 1 | X28: RCC_COLUMN | Z28: 04 1ST LEVEL | AA28: Concrete-Rectangular-Column: SW6 - 400 X 600 | AB28: 2JGI2Z2THB_wudpkjjxw_o | AC28: By Type | AD28: 03 PLINTH LEVEL
A29: 3084332 | B29: 7.515 | C29: COLUMN <40 mm> | D29: M40 | E29: 0 | F29: Yes | G29: 3076717 | H29: 5550 | I29: 1.665 | J29: 03 PLINTH LEVEL | K29: 0 | L29: Vertical | M29: COLUMN <40 mm> | N29: New Construction | O29: C6 - 300 X 1000 | P29: Yes | Q29: 1.67 m³ | R29: Concrete-Rectangular-Column | S29: Structural Columns | T29: COLUMN <40 mm> | U29: No | V29: 5.55 | W29: 1 | X29: RCC_COLUMN | Z29: 04 1ST LEVEL | AA29: Concrete-Rectangular-Column: C6 - 300 X 1000 | AB29: 2JGI2Z2THB_wudpkjjxw_u | AC29: By Type | AD29: 03 PLINTH LEVEL
A30: 3084334 | B30: 7.575 | C30: COLUMN <40 mm> | D30: M40 | E30: 0 | F30: Yes | G30: 3076752 | H30: 5550 | I30: 1.998 | J30: 03 PLINTH LEVEL | K30: 0 | L30: Vertical | M30: COLUMN <40 mm> | N30: New Construction | O30: C5 - 400 X 900 | P30: Yes | Q30: 2.00 m³ | R30: Concrete-Rectangular-Column | S30: Structural Columns | T30: COLUMN <40 mm> | U30: No | V30: 5.55 | W30: 1 | X30: RCC_COLUMN | Z30: 04 1ST LEVEL | AA30: Concrete-Rectangular-Column: C5 - 400 X 900 | AB30: 2JGI2Z2THB_wudpkjjxw_w | AC30: By Type | AD30: 03 PLINTH LEVEL
A31: 3084336 | B31: 7.575 | C31: COLUMN <40 mm> | D31: M40 | E31: 0 | F31: Yes | G31: 3076778 | H31: 5550 | I31: 1.998 | J31: 03 PLINTH LEVEL | K31: 0 | L31: Vertical | M31: COLUMN <40 mm> | N31: New Construction | O31: C4 - 400 X 900 | P31: Yes | Q31: 2.00 m³ | R31: Concrete-Rectangular-Column | S31: Structural Columns | T31: COLUMN <40 mm> | U31: No | V31: 5.55 | W31: 1 | X31: RCC_COLUMN | Z31: 04 1ST LEVEL | AA31: Concrete-Rectangular-Column: C4 - 400 X 900 | AB31: 2JGI2Z2THB_wudpkjjxw_a | AC31: By Type | AD31: 03 PLINTH LEVEL
... A35: 3105514 | B35: 20.07 | C35: COLUMN <40 mm> | D35: M40 | E35: 0 | F35: Yes | G35: 3076639 | H35: 5550 | I35: 6.66 | J35: 03 PLINTH LEVEL | K35: 0 | L35: Vertical | M35: COLUMN <40 mm> | N35: New Construction | O35: SW7 - 400 X 3000 | P35: Yes | Q35: 6.66 m³ | R35: Concrete-Rectangular-Column | S35: Structural Columns | T35: COLUMN <40 mm> | U35: No | V35: 5.55 | W35: 1 | X35: RCC_COLUMN | Z35: 04 1ST LEVEL | AA35: Concrete-Rectangular-Column: SW7 - 400 X 3000 | AB35: 0wOuN0$KH13wHCGl$5xo0c | AC35: By Type | AD35: 03 PLINTH LEVEL
A36: 3118481 | B36: 3.81 | C36: COLUMN <40 mm> | D36: M40 | E36: 0 | F36: Yes | G36: 2270699 | H36: 2950 | I36: 0.7965 | J36: 04 1ST LEVEL | K36: 0 | L36: Vertical | M36: COLUMN <40 mm> | N36: New Construction | O36: C1 - 300 X 900 | P36: Yes | Q36: 0.80 m³ | R36: Concrete-Rectangular-Column | S36: Structural Columns | T36: COLUMN <40 mm> | U36: No | V36: 2.95 | W36: 1 | X36: RCC_COLUMN | Y36: P31 | Z36: 05 2ND LEVEL | AA36: Concrete-Rectangular-Column: C1 - 300 X 900 | AB36: 0g26lkPdX4oOgZBW9zmKal | AC36: By Type | AD36: 04 1ST LEVEL
A37: 3118483 | B37: 3.485 | C37: COLUMN <40 mm> | D37: M40 | E37: 0 | F37: Yes | G37: 3113818 | H37: 2950 | I37: 0.708 | J37: 04 1ST LEVEL | K37: 0 | L37: Vertical | M37: COLUMN <40 mm> | N37: New Construction | O37: C2 - 300 X 800 | P37: Yes | Q37: 0.71 m³ | R37: Concrete-Rectangular-Column | S37: Structural Columns | T37: COLUMN <40 mm> | U37: No | V37: 2.95 | W37: 1 | X37: RCC_COLUMN | Z37: 05 2ND LEVEL | AA37: Concrete-Rectangular-Column: C2 - 300 X 800 | AB37: 0g26lkPdX4oOgZBW9zmKaj | AC37: By Type | AD37: 04 1ST LEVEL
A38: 3118485 | B38: 4.235 | C38: COLUMN <40 mm> | D38: M40 | E38: 0 | F38: Yes | G38: 3072865 | H38: 2950 | I38: 1.18 | J38: 04 1ST LEVEL | K38: 0 | L38: Vertical | M38: COLUMN <40 mm> | N38: New Construction | O38: C3 - 500 X 800 | P38: Yes | Q38: 1.18 m³ | R38: Concrete-Rectangular-Column | S38: Structural Columns | T38: COLUMN <40 mm> | U38: No | V38: 2.95 | W38: 1 | X38: RCC_COLUMN | Z38: 05 2ND LEVEL | AA38: Concrete-Rectangular-Column: C3 - 500 X 800 | AB38: 0g26lkPdX4oOgZBW9zmKah | AC38: By Type | AD38: 04 1ST LEVEL
A39: 3118487 | B39: 4.2175 | C39: COLUMN <40 mm> | D39: M40 | E39: 0 | F39: Yes | G39: 3080622 | H39: 2950 | I39: 1.1284 | J39: 04 1ST LEVEL | K39: 0 | L39: Vertical | M39: COLUMN <40 mm> | N39: New Construction | O39: SW1- 450 X 850 | P39: Yes | Q39: 1.13 m³ | R39: Concrete-Rectangular-Column | S39: Structural Columns | T39: COLUMN <40 mm> | U39: No | V39: 2.95 | W39: 1 | X39: RCC_COLUMN | Z39: 05 2ND LEVEL | AA39: Concrete-Rectangular-Column: SW1- 450 X 850 | AB39: 0g26lkPdX4oOgZBW9zmKaf | AC39: By Type | AD39: 04 1ST LEVEL
A40: 3118489 | B40: 6.9775 | C40: COLUMN <40 mm> | D40: M40 | E40: 0 | F40: Yes | G40: 3072997 | H40: 2950 | I40: 1.4381 | J40: 04 1ST LEVEL | K40: 0 | L40: Vertical | M40: COLUMN <40 mm> | N40: New Construction | O40: SW3 - 250 X 1950 | P40: Yes | Q40: 1.44 m³ | R40: Concrete-Rectangular-Column | S40: Structural Columns | T40: COLUMN <40 mm> | U40: No | V40: 2.95 | W40: 1 | X40: RCC_COLUMN | Z40: 05 2ND LEVEL | AA40: Concrete-Rectangular-Column: SW3 - 250 X 1950 | AB40: 0g26lkPdX4oOgZBW9zmKad | AC40: By Type | AD40: 04 1ST LEVEL
A41: 3118491 | B41: 1.535 | C41: COLUMN <40 mm> | D41: M40 | E41: 0 | F41: Yes | G41: 3073021 | H41: 2950 | I41: 0.177 | J41: 04 1ST LEVEL | K41: 0 | L41: Vertical | M41: COLUMN <40 mm> | N41: New Construction | O41: SW3 - 200 X 300 | P41: Yes | Q41: 0.18 m³ | R41: Concrete-Rectangular-Column | S41: Structural Columns | T41: COLUMN <40 mm> | U41: No | V41: 2.95 | W41: 1 | X41: RCC_COLUMN | Z41: 05 2ND LEVEL | AA41: Concrete-Rectangular-Column: SW3 - 200 X 300 | AB41: 0g26lkPdX4oOgZBW9zmKab | AC41: By Type | AD41: 04 1ST LEVEL
A42: 3118493 | B42: 6.9775 | C42: COLUMN <40 mm> | D42: M40 | E42: 0 | F42: Yes | G42: 3075811 | H42: 2950 | I42: 1.4381 | J42: 04 1ST LEVEL | K42: 0 | L42: Vertical | M42: COLUMN <40 mm> | N42: New Construction | O42: SW3A - 250 X 1950 | P42: Yes | Q42: 1.44 m³ | R42: Concrete-Rectangular-Column | S42: Structural Columns | T42: COLUMN <40 mm> | U42: No | V42: 2.95 | W42: 1 | X42: RCC_COLUMN | Z42: 05 2ND LEVEL | AA42: Concrete-Rectangular-Column: SW3A - 250 X 1950 | AB42: 0g26lkPdX4oOgZBW9zmKaZ | AC42: By Type | AD42: 04 1ST LEVEL
A43: 3118495 | B43: 2.8975 | C43: COLUMN <40 mm> | D43: M40 | E43: 0 | F43: Yes | G43: 3075838 | H43: 2950 | I43: 0.4978 | J43: 04 1ST LEVEL | K43: 0 | L43: Vertical | M43: COLUMN <40 mm> | N43: New Construction | O43: SW3A - 250 X 675 | P43: Yes | Q43: 0.50 m³ | R43: Concrete-Rectangular-Column | S43: Structural Columns | T43: COLUMN <40 mm> | U43: No | V43: 2.95 | W43: 1 | X43: RCC_COLUMN | Z43: 05 2ND LEVEL | AA43: Concrete-Rectangular-Column: SW3A - 250 X 675 | AB43: 0g26lkPdX4oOgZBW9zmKaX | AC43: By Type | AD43: 04 1ST LEVEL
A44: 3118499 | B44: 6.1775 | C44: COLUMN <40 mm> | D44: M40 | E44: 0 | F44: Yes | G44: 3076022 | H44: 2950 | I44: 1.2537 | J44: 04 1ST LEVEL | K44: 0 | L44: Vertical | M44: COLUMN <40 mm> | N44: New Construction | O44: SW4 - 250 X 1700 | P44: Yes | Q44: 1.25 m³ | R44: Concrete-Rectangular-Column | S44: Structural Columns | T44: COLUMN <40 mm> | U44: No | V44: 2.95 | W44: 1 | X44: RCC_COLUMN | Z44: 05 2ND LEVEL | AA44: Concrete-Rectangular-Column: SW4 - 250 X 1700 | AB44: 0g26lkPdX4oOgZBW9zmKaT | AC44: By Type | AD44: 04 1ST LEVEL
...

Sheet Slab
A1: Element ID | B1: Qty: Area (m2) | C1: Elevation at Top Core | D1: Rebar Cover - Other Faces | E1: Structural | F1: GRADE OF CONCRETE | G1: Type Id | H1: Length | I1: Qty: Volume (m3) | J1: Width | K1: Elevation at Bottom Survey | L1: Related to Mass | M1: Rebar Cover - Bottom Face | N1: Phase Created | O1: Type | P1: Core Thickness | Q1: Elevation at Bottom Core | R1: Volume | S1: Family | T1: Perimeter | U1: Category | V1: Rebar Cover - Top Face | W1: Elevation at Top | X1: Thickness | Y1: Has Association | Z1: Area | AA1: Height Offset From Level | AB1: Qty: Count | AC1: ID_UNMT | AD1: Elevation at Bottom | AE1: Elevation at Top Survey | AF1: Family and Type | AG1: IfcGUID | AH1: Qty: Thickness (m) | AI1: Export to IFC | AJ1: Level
A2: 3070305 | B2: 3 | C2: -2350 | D2: FOUNDATION <50 mm> | E2: Yes | F2: M40 | G2: 3070326 | H2: 1500 | I2: 1.8 | J2: 2000 | K2: -2950 | L2: No | N2: New Construction | O2: F1 - 600MM | P2: 600 | Q2: -2950 | R2: 1.80 m³ | S2: Foundation Slab | T2: 7000 | U2: Structural Foundations | V2: FOUNDATION <50 mm> | W2: -2350 | X2: 600 | Y2: No | Z2: 3 m² | AA2: 0 | AB2: 1 | AC2: F1 | AD2: -2950 | AE2: -2350 | AF2: Foundation Slab: F1 - 600MM | AG2: 33AYsgylX80BV2OFfKznor | AH2: 0.6 | AI2: By Type | AJ2: 01 FOUNDATION LEVEL
A3: 3070393 | B3: 3.74 | C3: -2950 | D3: COLUMN <40 mm> | E3: Yes | F3: M10 | G3: 2255647 | H3: 1700 | I3: 0.374 | J3: 2200 | K3: -3050 | L3: No | M3: COLUMN <40 mm> | N3: New Construction | O3: PCC | P3: 100 | Q3: -3050 | R3: 0.37 m³ | S3: Foundation Slab | T3: 7800 | U3: Structural Foundations | V3: COLUMN <40 mm> | W3: -2950 | X3: 100 | Y3: No | Z3: 4 m² | AA3: -600 | AB3: 1 | AC3: PCC_FOOTING | AD3: -3050 | AE3: -2950 | AF3: Foundation Slab: PCC | AG3: 33AYsgylX80BV2OFfKznnj | AH3: 0.1 | AI3: By Type | AJ3: 01 FOUNDATION LEVEL
A4: 3070773 | B4: 3 | C4: -2350 | D4: FOUNDATION <50 mm> | E4: Yes | F4: M40 | G4: 3070326 | H4: 1500 | I4: 1.8 | J4: 2000 | K4: -2950 | L4: No | N4: New Construction | O4: F1 - 600MM | P4: 600 | Q4: -2950 | R4: 1.80 m³ | S4: Foundation Slab | T4: 7000 | U4: Structural Foundations | V4: FOUNDATION <50 mm> | W4: -2350 | X4: 600 | Y4: No | Z4: 3 m² | AA4: 0 | AB4: 1 | AC4: F1 | AD4: -2950 | AE4: -2350 | AF4: Foundation Slab: F1 - 600MM | AG4: 1OIgpuqiH33Qs8VR23YRZc | AH4: 0.6 | AI4: By Type | AJ4: 01 FOUNDATION LEVEL
A5: 3070782 | B5: 3.74 | C5: -2950 | D5: COLUMN <40 mm> | E5: Yes | F5: M10 | G5: 2255647 | H5: 1700 | I5: 0.374 | J5: 2200 | K5: -3050 | L5: No | M5: COLUMN <40 mm> | N5: New Construction | O5: PCC | P5: 100 | Q5: -3050 | R5: 0.37 m³ | S5: Foundation Slab | T5: 7800 | U5: Structural Foundations | V5: COLUMN <40 mm> | W5: -2950 | X5: 100 | Y5: No | Z5: 4 m² | AA5: -600 | AB5: 1 | AC5: PCC_FOOTING | AD5: -3050 | AE5: -2950 | AF5: Foundation Slab: PCC | AG5: 1OIgpuqiH33Qs8VR23YRZj | AH5: 0.1 | AI5: By Type | AJ5: 01 FOUNDATION LEVEL
A6: 3070818 | B6: 3.96 | C6: -2350 | D6: FOUNDATION <50 mm> | E6: Yes | F6: M40 | G6: 3071073 | H6: 2200 | I6: 2.772 | J6: 1800 | K6: -3050 | L6: No | N6: New Construction | O6: F2 - 700MM | P6: 700 | Q6: -3050 | R6: 2.77 m³ | S6: Foundation Slab | T6: 8000 | U6: Structural Foundations | V6: FOUNDATION <50 mm> | W6: -2350 | X6: 700 | Y6: No | Z6: 4 m² | AA6: 0 | AB6: 1 | AC6: F2 | AD6: -3050 | AE6: -2350 | AF6: Foundation Slab: F2 - 700MM | AG6: 3_y0Jm7LL5Uf8xXWt_c0b1 | AH6: 0.7 | AI6: By Type | AJ6: 01 FOUNDATION LEVEL
A7: 3070827 | B7: 4.8 | C7: -3050 | D7: COLUMN <40 mm> | E7: Yes | F7: M10 | G7: 2255647 | H7: 2400 | I7: 0.48 | J7: 2000 | K7: -3150 | L7: No | M7: COLUMN <40 mm> | N7: New Construction | O7: PCC | P7: 100 | Q7: -3150 | R7: 0.48 m³ | S7: Foundation Slab | T7: 8800 | U7: Structural Foundations | V7: COLUMN <40 mm> | W7: -3050 | X7: 100 | Y7: No | Z7: 5 m² | AA7: -700 | AB7: 1 | AC7: PCC_FOOTING | AD7: -3150 | AE7: -3050 | AF7: Foundation Slab: PCC | AG7: 3_y0Jm7LL5Uf8xXWt_c0b8 | AH7: 0.1 | AI7: By Type | AJ7: 01 FOUNDATION LEVEL
A8: 3070960 | B8: 3.96 | C8: -2350 | D8: FOUNDATION <50 mm> | E8: Yes | F8: M40 | G8: 3071073 | H8: 2200 | I8: 2.772 | J8: 1800 | K8: -3050 | L8: No | N8: New Construction | O8: F2 - 700MM | P8: 700 | Q8: -3050 | R8: 2.77 m³ | S8: Foundation Slab | T8: 8000 | U8: Structural Foundations | V8: FOUNDATION <50 mm> | W8: -2350 | X8: 700 | Y8: No | Z8: 4 m² | AA8: 0 | AB8: 1 | AC8: F2 | AD8: -3050 | AE8: -2350 | AF8: Foundation Slab: F2 - 700MM | AG8: 2vYX391Bf25OBSrHEK9sy$ | AH8: 0.7 | AI8: By Type | AJ8: 01 FOUNDATION LEVEL
A9: 3070969 | B9: 4.8 | C9: -3050 | D9: COLUMN <40 mm> | E9: Yes | F9: M10 | G9: 2255647 | H9: 2400 | I9: 0.48 | J9: 2000 | K9: -3150 | L9: No | M9: COLUMN <40 mm> | N9: New Construction | O9: PCC | P9: 100 | Q9: -3150 | R9: 0.48 m³ | S9: Foundation Slab | T9: 8800 | U9: Structural Foundations | V9: COLUMN <40 mm> | W9: -3050 | X9: 100 | Y9: No | Z9: 5 m² | AA9: -700 | AB9: 1 | AC9: PCC_FOOTING | AD9: -3150 | AE9: -3050 | AF9: Foundation Slab: PCC | AG9: 2vYX391Bf25OBSrHEK9sys | AH9: 0.1 | AI9: By Type | AJ9: 01 FOUNDATION LEVEL
A10: 3071149 | B10: 3.51 | C10: -2350 | D10: FOUNDATION <50 mm> | E10: Yes | F10: M40 | G10: 3071090 | H10: 2700 | I10: 2.457 | J10: 1300 | K10: -3050 | L10: No | N10: New Construction | O10: F3 - 700MM | P10: 700 | Q10: -3050 | R10: 2.46 m³ | S10: Foundation Slab | T10: 8000 | U10: Structural Foundations | V10: FOUNDATION <50 mm> | W10: -2350 | X10: 700 | Y10: No | Z10: 4 m² | AA10: 0 | AB10: 1 | AC10: F3 | AD10: -3050 | AE10: -2350 | AF10: Foundation Slab: F3 - 700MM | AG10: 0pBnFJmFzFEwLCxY_KwjGT | AH10: 0.7 | AI10: By Type | AJ10: 01 FOUNDATION LEVEL
A11: 3071158 | B11: 4.35 | C11: -3050 | D11: COLUMN <40 mm> | E11: Yes | F11: M10 | G11: 2255647 | H11: 2900 | I11: 0.435 | J11: 1500 | K11: -3150 | L11: No | M11: COLUMN <40 mm> | N11: New Construction | O11: PCC | P11: 100 | Q11: -3150 | R11: 0.44 m³ | S11: Foundation Slab | T11: 8800 | U11: Structural Foundations | V11: COLUMN <40 mm> | W11: -3050 | X11: 100 | Y11: No | Z11: 4 m² | AA11: -700 | AB11: 1 | AC11: PCC_FOOTING | AD11: -3150 | AE11: -3050 | AF11: Foundation Slab: PCC | AG11: 0pBnFJmFzFEwLCxY_KwjG6 | AH11: 0.1 | AI11: By Type | AJ11: 01 FOUNDATION LEVEL
A12: 3071322 | B12: 2.34 | C12: -2350 | D12: FOUNDATION <50 mm> | E12: Yes | F12: M40 | G12: 3175964 | H12: 1300 | I12: 1.17 | J12: 1800 | K12: -2850 | L12: No | N12: New Construction | O12: F5 - 500MM | P12: 500 | Q12: -2850 | R12: 1.17 m³ | S12: Foundation Slab | T12: 6200 | U12: Structural Foundations | V12: FOUNDATION <50 mm> | W12: -2350 | X12: 500 | Y12: No | Z12: 2 m² | AA12: 0 | AB12: 1 | AC12: F5 | AD12: -2850 | AE12: -2350 | AF12: Foundation Slab: F5 - 500MM | AG12: 2tUNbxU1T0IBvn6Zylc4PG | AH12: 0.5 | AI12: By Type | AJ12: 01 FOUNDATION LEVEL
A13: 3071331 | B13: 3 | C13: -2850 | D13: COLUMN <40 mm> | E13: Yes | F13: M10 | G13: 2255647 | H13: 1500 | I13: 0.3 | J13: 2000 | K13: -2950 | L13: No | M13: COLUMN <40 mm> | N13: New Construction | O13: PCC | P13: 100 | Q13: -2950 | R13: 0.30 m³ | S13: Foundation Slab | T13: 7000 | U13: Structural Foundations | V13: COLUMN <40 mm> | W13: -2850 | X13: 100 | Y13: No | Z13: 3 m² | AA13: -500 | AB13: 1 | AC13: PCC_FOOTING | AD13: -2950 | AE13: -2850 | AF13: Foundation Slab: PCC | AG13: 2tUNbxU1T0IBvn6Zylc4Pf | AH13: 0.1 | AI13: By Type | AJ13: 01 FOUNDATION LEVEL
A14: 3071454 | B14: 66.0625 | C14: -2350 | D14: FOUNDATION <50 mm> | E14: Yes | F14: M40 | G14: 3071368 | H14: 7550 | I14: 49.5469 | J14: 8750 | K14: -3100 | L14: No | N14: New Construction | O14: CF1 - 750MM | P14: 750 | Q14: -3100 | R14: 49.55 m³ | S14: Foundation Slab | T14: 32600 | U14: Structural Foundations | V14: FOUNDATION <50 mm> | W14: -2350 | X14: 750 | Y14: No | Z14: 66 m² | AA14: 0 | AB14: 1 | AC14: CF1 | AD14: -3100 | AE14: -2350 | AF14: Foundation Slab: CF1 - 750MM | AG14: 0yn1G3deX64RIHl7h1zcMy | AH14: 0.75 | AI14: By Type | AJ14: 01 FOUNDATION LEVEL
A15: 3071463 | B15: 69.3625 | C15: -3100 | D15: COLUMN <40 mm> | E15: Yes | F15: M10 | G15: 2255647 | H15: 7750 | I15: 6.9363 | J15: 8950 | K15: -3200 | L15: No | M15: COLUMN <40 mm> | N15: New Construction | O15: PCC | P15: 100 | Q15: -3200 | R15: 6.94 m³ | S15: Foundation Slab | T15: 33400 | U15: Structural Foundations | V15: COLUMN <40 mm> | W15: -3100 | X15: 100 | Y15: No | Z15: 69 m² | AA15: -750 | AB15: 1 | AC15: PCC_FOOTING | AD15: -3200 | AE15: -3100 | AF15: Foundation Slab: PCC | AG15: 0yn1G3deX64RIHl7h1zcM5 | AH15: 0.1 | AI15: By Type | AJ15: 01 FOUNDATION LEVEL
A16: 3071667 | B16: 28.9418 | C16: -2350 | D16: FOUNDATION <50 mm> | E16: Yes | F16: M40 | G16: 3071385 | H16: 4000 | I16: 21.7063 | J16: 8300 | K16: -3100 | L16: No | N16: New Construction | O16: CF2 - 750MM | P16: 750 | Q16: -3100 | R16: 21.71 m³ | S16: Foundation Slab | T16: 24600 | U16: Structural Foundations | V16: FOUNDATION <50 mm> | W16: -2350 | X16: 750 | Y16: No | Z16: 29 m² | AA16: 0 | AB16: 1 | AC16: CF2 | AD16: -3100 | AE16: -2350 | AF16: Foundation Slab: CF2 - 750MM | AG16: 1iNhjbtjT27ezT3D1vCLgG | AH16: 0.75 | AI16: By Type | AJ16: 01 FOUNDATION LEVEL
A17: 3071676 | B17: 31.4418 | C17: -3100 | D17: COLUMN <40 mm> | E17: Yes | F17: M10 | G17: 2255647 | H17: 4200 | I17: 3.1442 | J17: 8500 | K17: -3200 | L17: No | M17: COLUMN <40 mm> | N17: New Construction | O17: PCC | P17: 100 | Q17: -3200 | R17: 3.14 m³ | S17: Foundation Slab | T17: 25400 | U17: Structural Foundations | V17: COLUMN <40 mm> | W17: -3100 | X17: 100 | Y17: No | Z17: 31 m² | AA17: -750 | AB17: 1 | AC17: PCC_FOOTING | AD17: -3200 | AE17: -3100 | AF17: Foundation Slab: PCC | AG17: 1iNhjbtjT27ezT3D1vCLgV | AH17: 0.1 | AI17: By Type | AJ17: 01 FOUNDATION LEVEL
A18: 3087101 | B18: 15.2075 | C18: 450 | D18: SLAB <20 mm> | E18: Yes | F18: M30 | G18: 2432663 | H18: 3850 | I18: 2.2811 | J18: 3950 | K18: 300 | L18: No | M18: SLAB <20 mm> | N18: New Construction | O18: GRADE SLAB | P18: 150 | Q18: 300 | R18: 2.28 m³ | S18: Foundation Slab | T18: 15600 | U18: Structural Foundations | V18: SLAB <20 mm> | W18: 450 | X18: 150 | Y18: No | Z18: 15 m² | AA18: 0 | AB18: 1 | AC18: GS | AD18: 300 | AE18: 450 | AF18: Foundation Slab: GRADE SLAB | AG18: 1ndm0CiUv2$BFHfN_6Vb0K | AH18: 0.15 | AI18: By Type | AJ18: 03 PLINTH LEVEL
A19: 3087176 | B19: 5.882 | C19: 450 | D19: SLAB <20 mm> | E19: Yes | F19: M30 | G19: 2432663 | H19: 4500 | I19: 0.8823 | J19: 1400 | K19: 300 | L19: No | M19: SLAB <20 mm> | N19: New Construction | O19: GRADE SLAB | P19: 150 | Q19: 300 | R19: 0.88 m³ | S19: Foundation Slab | T19: 11800 | U19: Structural Foundations | V19: SLAB <20 mm> | W19: 450 | X19: 150 | Y19: No | Z19: 6 m² | AA19: 0 | AB19: 1 | AC19: GS | AD19: 300 | AE19: 450 | AF19: Foundation Slab: GRADE SLAB | AG19: 1ndm0CiUv2$BFHfN_6Vb6X | AH19: 0.15 | AI19: By Type | AJ19: 03 PLINTH LEVEL
